Workbook
Name Alimentação: Modelo!$N$4:$N$8
Name Despesas: Modelo!$N$19:$N$25
Name Educação: Modelo!$N$37:$N$43
Name Imprevistos: Modelo!$N$53:$N$59
Name Lazer: Modelo!$N$10:$N$17
Name Moradia: Modelo!#REF!
Name Saúde: Modelo!$N$45:$N$51
Name Transporte: Modelo!$N$29:$N$35

Sheet Jan
B2: JAN | C2: entradas | D2: valor | F2: Saldo mensal
B3: salário | F3: =SUM(D3,D5,D6,D7,D4) -> 0 | I3: data
B4: Fotografia | D4: =SUM(P10:P25) -> 0 | F4: =SUM(F11:F32) -> 0 | I4: =TODAY() -> 46002
B5: extra 2 | F5: =D4 -> 0 | I5: ultimo update
B6: extra 3 | F6: =SUM(K11:K22) -> 0 | I6: 45847
F7: =F3-F4-F6 -> 0
B9: Variados | H9: Fixos | M9: Eventos | N9: Data | O9: Descrição | P9: Entradas
B10: data | C10: topico | D10: sub-tópico | E10: descrição | F10: valor | H10: data | I10: Topico | J10: sub-tópico | K10: valor
B35: Alimentação | C35: Doces | D35: =SUMIF($D$11:$D$32,C35,$F$11:$F$32) -> 0 | H35: Internet | I35: =SUMIF($I$11:$I$22,H35,$K$11:$K$22) -> 0
B36: =SUM(D35:D39) -> 0 | C36: Padaria | D36: =SUMIF($D$11:$D$32,C36,$F$11:$F$32) -> 0 | H36: Planos/assinaturas | I36: =SUMIF($I$11:$I$22,H36,$K$11:$K$22) -> 0
C37: Almoço fora | D37: =SUMIF($D$11:$D$32,C37,$F$11:$F$32) -> 0 | H37: Agua | I37: =SUMIF($I$11:$I$22,H37,$K$11:$K$22) -> 0
C38: Lanches / Snacks | D38: =SUMIF($D$11:$D$32,C38,$F$11:$F$32) -> 0 | H38: Luz | I38: =SUMIF($I$11:$I$22,H38,$K$11:$K$22) -> 0
D39: =SUMIF($D$11:$D$32,C39,$F$11:$F$32) -> 0 | H39: Gasolina | I39: =SUMIF($I$11:$I$22,H39,$K$11:$K$22) -> 0
H40: Dizimos | I40: =SUMIF($I$11:$I$22,H40,$K$11:$K$22) -> 0
B41: Lazer | C41: Delivery (iFood, etc) | D41: =SUMIF($D$11:$D$32,C41,$F$11:$F$32) -> 0 | H41: Ofertas | I41: =SUMIF($I$11:$I$22,H41,$K$11:$K$22) -> 0
B42: =SUBTOTAL(9,D41:D48) -> 0 | C42: Cinema / Shows | D42: =SUMIF($D$11:$D$32,C42,$F$11:$F$32) -> 0 | H42: Parcelas | I42: =SUMIF($I$11:$I$22,H42,$K$11:$K$22) -> 0
C43: Passeios / Viagens | D43: =SUMIF($D$11:$D$32,C43,$F$11:$F$32) -> 0 | H43: Saúde | I43: =SUMIF($I$11:$I$22,H43,$K$11:$K$22) -> 0
C44: Compras por impulso (não essenciais) | D44: =SUMIF($D$11:$D$32,C44,$F$11:$F$32) -> 0 | H44: Investimento | I44: =SUMIF($I$11:$I$22,H44,$K$11:$K$22) -> 0
C45: Jogos / Games / Aplicativos pagos | D45: =SUMIF($D$11:$D$32,C45,$F$11:$F$32) -> 0 | I45: =SUMIF($I$11:$I$22,H45,$K$11:$K$22) -> 0
C46: Saídas com amigos | D46: =SUMIF($D$11:$D$32,C46,$F$11:$F$32) -> 0
D47: =SUMIF($D$11:$D$32,C47,$F$11:$F$32) -> 0
D48: =SUMIF($D$11:$D$32,C48,$F$11:$F$32) -> 0
B50: Despesas | C50: Presentes e datas comemorativas | D50: =SUMIF($D$11:$D$32,C50,$F$11:$F$32) -> 0
B51: =SUM(D50:D56) -> 0 | C51: Doações / Contribuições | D51: =SUMIF($D$11:$D$32,C51,$F$11:$F$32) -> 0
C52: Taxas bancárias / Pix por engano | D52: =SUMIF($D$11:$D$32,C52,$F$11:$F$32) -> 0
C53: Compras online aleatórias | D53: =SUMIF($D$11:$D$32,C53,$F$11:$F$32) -> 0
C54: Manutenção da casa (lâmpada, pilha, etc) | D54: =SUMIF($D$11:$D$32,C54,$F$11:$F$32) -> 0
C55: Gastos pessoais (roupas, acessórios) | D55: =SUMIF($D$11:$D$32,C55,$F$11:$F$32) -> 0
D56: =SUMIF($D$11:$D$32,C56,$F$11:$F$32) -> 0
B58: Transporte | C58: Acessório | D58: =SUMIF($D$11:$D$32,C58,$F$11:$F$32) -> 0
B59: =SUM(D58:D64) -> 0 | C59: Uber / Táxi | D59: =SUMIF($D$11:$D$32,C59,$F$11:$F$32) -> 0
C60: Ônibus / Metrô | D60: =SUMIF($D$11:$D$32,C60,$F$11:$F$32) -> 0
C61: Estacionamento | D61: =SUMIF($D$11:$D$32,C61,$F$11:$F$32) -> 0
C62: Manutenção (óleo, pneu, etc) | D62: =SUMIF($D$11:$D$32,C62,$F$11:$F$32) -> 0
C63: Multas / Documentação | D63: =SUMIF($D$11:$D$32,C63,$F$11:$F$32) -> 0
D64: =SUMIF($D$11:$D$32,C64,$F$11:$F$32) -> 0
B66: Educação | C66: Livros | D66: =SUMIF($D$11:$D$32,C66,$F$11:$F$32) -> 0
B67: =SUM(D66:D72) -> 0 | C67: Cursos online (Udemy, Alura, etc) | D67: =SUMIF($D$11:$D$32,C67,$F$11:$F$32) -> 0
C68: Material escolar / didático | D68: =SUMIF($D$11:$D$32,C68,$F$11:$F$32) -> 0
C69: Apostilas | D69: =SUMIF($D$11:$D$32,C69,$F$11:$F$32) -> 0
...

Sheet Fev
B2: Fev | C2: entradas | D2: valor | F2: Saldo mensal
B3: salário | F3: =SUM(D3,D5,D6,D7,D4) -> 0 | I3: data
B4: Fotografia | D4: =SUM(P10:P25) -> 0 | F4: =SUM(F11:F32) -> 0 | I4: =TODAY() -> 46002
B5: extra 2 | F5: =D4 -> 0 | I5: ultimo update
B6: extra 3 | F6: =SUM(K11:K22) -> 0 | I6: 45847
B7: Saldo | D7: =Jan!F7 -> 0 | F7: =F3-F4-F6 -> 0
B9: Variados | H9: Fixos | M9: Eventos | N9: Data | O9: Descrição | P9: Entradas
B10: data | C10: topico | D10: sub-tópico | E10: descrição | F10: valor | H10: data | I10: Topico | J10: sub-tópico | K10: valor
B35: Alimentação | C35: Doces | D35: =SUMIF($D$11:$D$32,C35,$F$11:$F$32) -> 0 | H35: Internet | I35: =SUMIF($I$11:$I$22,H35,$K$11:$K$22) -> 0
B36: =SUM(D35:D39) -> 0 | C36: Padaria | D36: =SUMIF($D$11:$D$32,C36,$F$11:$F$32) -> 0 | H36: Planos/assinaturas | I36: =SUMIF($I$11:$I$22,H36,$K$11:$K$22) -> 0
C37: Almoço fora | D37: =SUMIF($D$11:$D$32,C37,$F$11:$F$32) -> 0 | H37: Agua | I37: =SUMIF($I$11:$I$22,H37,$K$11:$K$22) -> 0
C38: Lanches / Snacks | D38: =SUMIF($D$11:$D$32,C38,$F$11:$F$32) -> 0 | H38: Luz | I38: =SUMIF($I$11:$I$22,H38,$K$11:$K$22) -> 0
D39: =SUMIF($D$11:$D$32,C39,$F$11:$F$32) -> 0 | H39: Gasolina | I39: =SUMIF($I$11:$I$22,H39,$K$11:$K$22) -> 0
H40: Dizimos | I40: =SUMIF($I$11:$I$22,H40,$K$11:$K$22) -> 0
B41: Lazer | C41: Delivery (iFood, etc) | D41: =SUMIF($D$11:$D$32,C41,$F$11:$F$32) -> 0 | H41: Ofertas | I41: =SUMIF($I$11:$I$22,H41,$K$11:$K$22) -> 0
B42: =SUBTOTAL(9,D41:D48) -> 0 | C42: Cinema / Shows | D42: =SUMIF($D$11:$D$32,C42,$F$11:$F$32) -> 0 | H42: Parcelas | I42: =SUMIF($I$11:$I$22,H42,$K$11:$K$22) -> 0
C43: Passeios / Viagens | D43: =SUMIF($D$11:$D$32,C43,$F$11:$F$32) -> 0 | H43: Saúde | I43: =SUMIF($I$11:$I$22,H43,$K$11:$K$22) -> 0
C44: Compras por impulso (não essenciais) | D44: =SUMIF($D$11:$D$32,C44,$F$11:$F$32) -> 0 | H44: Investimento | I44: =SUMIF($I$11:$I$22,H44,$K$11:$K$22) -> 0
C45: Jogos / Games / Aplicativos pagos | D45: =SUMIF($D$11:$D$32,C45,$F$11:$F$32) -> 0 | I45: =SUMIF($I$11:$I$22,H45,$K$11:$K$22) -> 0
C46: Saídas com amigos | D46: =SUMIF($D$11:$D$32,C46,$F$11:$F$32) -> 0
D47: =SUMIF($D$11:$D$32,C47,$F$11:$F$32) -> 0
D48: =SUMIF($D$11:$D$32,C48,$F$11:$F$32) -> 0
B50: Despesas | C50: Presentes e datas comemorativas | D50: =SUMIF($D$11:$D$32,C50,$F$11:$F$32) -> 0
B51: =SUM(D50:D56) -> 0 | C51: Doações / Contribuições | D51: =SUMIF($D$11:$D$32,C51,$F$11:$F$32) -> 0
C52: Taxas bancárias / Pix por engano | D52: =SUMIF($D$11:$D$32,C52,$F$11:$F$32) -> 0
C53: Compras online aleatórias | D53: =SUMIF($D$11:$D$32,C53,$F$11:$F$32) -> 0
C54: Manutenção da casa (lâmpada, pilha, etc) | D54: =SUMIF($D$11:$D$32,C54,$F$11:$F$32) -> 0
C55: Gastos pessoais (roupas, acessórios) | D55: =SUMIF($D$11:$D$32,C55,$F$11:$F$32) -> 0
D56: =SUMIF($D$11:$D$32,C56,$F$11:$F$32) -> 0
B58: Transporte | C58: Acessório | D58: =SUMIF($D$11:$D$32,C58,$F$11:$F$32) -> 0
B59: =SUM(D58:D64) -> 0 | C59: Uber / Táxi | D59: =SUMIF($D$11:$D$32,C59,$F$11:$F$32) -> 0
C60: Ônibus / Metrô | D60: =SUMIF($D$11:$D$32,C60,$F$11:$F$32) -> 0
C61: Estacionamento | D61: =SUMIF($D$11:$D$32,C61,$F$11:$F$32) -> 0
C62: Manutenção (óleo, pneu, etc) | D62: =SUMIF($D$11:$D$32,C62,$F$11:$F$32) -> 0
C63: Multas / Documentação | D63: =SUMIF($D$11:$D$32,C63,$F$11:$F$32) -> 0
D64: =SUMIF($D$11:$D$32,C64,$F$11:$F$32) -> 0
B66: Educação | C66: Livros | D66: =SUMIF($D$11:$D$32,C66,$F$11:$F$32) -> 0
B67: =SUM(D66:D72) -> 0 | C67: Cursos online (Udemy, Alura, etc) | D67: =SUMIF($D$11:$D$32,C67,$F$11:$F$32) -> 0
C68: Material escolar / didático | D68: =SUMIF($D$11:$D$32,C68,$F$11:$F$32) -> 0
C69: Apostilas | D69: =SUMIF($D$11:$D$32,C69,$F$11:$F$32) -> 0
...

Sheet Mar
B2: MAR | C2: entradas | D2: valor | F2: Saldo mensal
B3: salário | F3: =SUM(D3,D5,D6,D7,D4) -> 0 | I3: data
B4: Fotografia | D4: =SUM(P10:P25) -> 0 | F4: =SUM(F11:F32) -> 0 | I4: =TODAY() -> 46002
B5: extra 2 | F5: =D4 -> 0 | I5: ultimo update
B6: extra 3 | F6: =SUM(K11:K22) -> 0 | I6: 45847
B7: Saldo | D7: =Fev!F7 -> 0 | F7: =F3-F4-F6 -> 0
B9: Variados | H9: Fixos | M9: Eventos | N9: Data | O9: Descrição | P9: Entradas
B10: data | C10: topico | D10: sub-tópico | E10: descrição | F10: valor | H10: data | I10: Topico | J10: sub-tópico | K10: valor
B35: Alimentação | C35: Doces | D35: =SUMIF($D$11:$D$32,C35,$F$11:$F$32) -> 0 | H35: Internet | I35: =SUMIF($I$11:$I$22,H35,$K$11:$K$22) -> 0
B36: =SUM(D35:D39) -> 0 | C36: Padaria | D36: =SUMIF($D$11:$D$32,C36,$F$11:$F$32) -> 0 | H36: Planos/assinaturas | I36: =SUMIF($I$11:$I$22,H36,$K$11:$K$22) -> 0
C37: Almoço fora | D37: =SUMIF($D$11:$D$32,C37,$F$11:$F$32) -> 0 | H37: Agua | I37: =SUMIF($I$11:$I$22,H37,$K$11:$K$22) -> 0
C38: Lanches / Snacks | D38: =SUMIF($D$11:$D$32,C38,$F$11:$F$32) -> 0 | H38: Luz | I38: =SUMIF($I$11:$I$22,H38,$K$11:$K$22) -> 0
D39: =SUMIF($D$11:$D$32,C39,$F$11:$F$32) -> 0 | H39: Gasolina | I39: =SUMIF($I$11:$I$22,H39,$K$11:$K$22) -> 0
H40: Dizimos | I40: =SUMIF($I$11:$I$22,H40,$K$11:$K$22) -> 0
B41: Lazer | C41: Delivery (iFood, etc) | D41: =SUMIF($D$11:$D$32,C41,$F$11:$F$32) -> 0 | H41: Ofertas | I41: =SUMIF($I$11:$I$22,H41,$K$11:$K$22) -> 0
B42: =SUBTOTAL(9,D41:D48) -> 0 | C42: Cinema / Shows | D42: =SUMIF($D$11:$D$32,C42,$F$11:$F$32) -> 0 | H42: Parcelas | I42: =SUMIF($I$11:$I$22,H42,$K$11:$K$22) -> 0
C43: Passeios / Viagens | D43: =SUMIF($D$11:$D$32,C43,$F$11:$F$32) -> 0 | H43: Saúde | I43: =SUMIF($I$11:$I$22,H43,$K$11:$K$22) -> 0
C44: Compras por impulso (não essenciais) | D44: =SUMIF($D$11:$D$32,C44,$F$11:$F$32) -> 0 | H44: Investimento | I44: =SUMIF($I$11:$I$22,H44,$K$11:$K$22) -> 0
C45: Jogos / Games / Aplicativos pagos | D45: =SUMIF($D$11:$D$32,C45,$F$11:$F$32) -> 0 | I45: =SUMIF($I$11:$I$22,H45,$K$11:$K$22) -> 0
C46: Saídas com amigos | D46: =SUMIF($D$11:$D$32,C46,$F$11:$F$32) -> 0
D47: =SUMIF($D$11:$D$32,C47,$F$11:$F$32) -> 0
D48: =SUMIF($D$11:$D$32,C48,$F$11:$F$32) -> 0
B50: Despesas | C50: Presentes e datas comemorativas | D50: =SUMIF($D$11:$D$32,C50,$F$11:$F$32) -> 0
B51: =SUM(D50:D56) -> 0 | C51: Doações / Contribuições | D51: =SUMIF($D$11:$D$32,C51,$F$11:$F$32) -> 0
C52: Taxas bancárias / Pix por engano | D52: =SUMIF($D$11:$D$32,C52,$F$11:$F$32) -> 0
C53: Compras online aleatórias | D53: =SUMIF($D$11:$D$32,C53,$F$11:$F$32) -> 0
C54: Manutenção da casa (lâmpada, pilha, etc) | D54: =SUMIF($D$11:$D$32,C54,$F$11:$F$32) -> 0
C55: Gastos pessoais (roupas, acessórios) | D55: =SUMIF($D$11:$D$32,C55,$F$11:$F$32) -> 0
D56: =SUMIF($D$11:$D$32,C56,$F$11:$F$32) -> 0
B58: Transporte | C58: Acessório | D58: =SUMIF($D$11:$D$32,C58,$F$11:$F$32) -> 0
B59: =SUM(D58:D64) -> 0 | C59: Uber / Táxi | D59: =SUMIF($D$11:$D$32,C59,$F$11:$F$32) -> 0
C60: Ônibus / Metrô | D60: =SUMIF($D$11:$D$32,C60,$F$11:$F$32) -> 0
C61: Estacionamento | D61: =SUMIF($D$11:$D$32,C61,$F$11:$F$32) -> 0
C62: Manutenção (óleo, pneu, etc) | D62: =SUMIF($D$11:$D$32,C62,$F$11:$F$32) -> 0
C63: Multas / Documentação | D63: =SUMIF($D$11:$D$32,C63,$F$11:$F$32) -> 0
D64: =SUMIF($D$11:$D$32,C64,$F$11:$F$32) -> 0
B66: Educação | C66: Livros | D66: =SUMIF($D$11:$D$32,C66,$F$11:$F$32) -> 0
B67: =SUM(D66:D72) -> 0 | C67: Cursos online (Udemy, Alura, etc) | D67: =SUMIF($D$11:$D$32,C67,$F$11:$F$32) -> 0
C68: Material escolar / didático | D68: =SUMIF($D$11:$D$32,C68,$F$11:$F$32) -> 0
C69: Apostilas | D69: =SUMIF($D$11:$D$32,C69,$F$11:$F$32) -> 0
...

Sheet Abr
B2: ABR | C2: entradas | D2: valor | F2: Saldo mensal
B3: salário | F3: =SUM(D3,D5,D6,D7,D4) -> 0 | I3: data
B4: Fotografia | D4: =SUM(P10:P25) -> 0 | F4: =SUM(F11:F32) -> 0 | I4: =TODAY() -> 46002
B5: extra 2 | F5: =D4 -> 0 | I5: ultimo update
B6: extra 3 | F6: =SUM(K11:K22) -> 0 | I6: 45847
B7: Saldo | D7: =Mar!F7 -> 0 | F7: =F3-F4-F6 -> 0
B9: Variados | H9: Fixos | M9: Eventos | N9: Data | O9: Descrição | P9: Entradas
B10: data | C10: topico | D10: sub-tópico | E10: descrição | F10: valor | H10: data | I10: Topico | J10: sub-tópico | K10: valor
B35: Alimentação | C35: Doces | D35: =SUMIF($D$11:$D$32,C35,$F$11:$F$32) -> 0 | H35: Internet | I35: =SUMIF($I$11:$I$22,H35,$K$11:$K$22) -> 0
B36: =SUM(D35:D39) -> 0 | C36: Padaria | D36: =SUMIF($D$11:$D$32,C36,$F$11:$F$32) -> 0 | H36: Planos/assinaturas | I36: =SUMIF($I$11:$I$22,H36,$K$11:$K$22) -> 0
C37: Almoço fora | D37: =SUMIF($D$11:$D$32,C37,$F$11:$F$32) -> 0 | H37: Agua | I37: =SUMIF($I$11:$I$22,H37,$K$11:$K$22) -> 0
C38: Lanches / Snacks | D38: =SUMIF($D$11:$D$32,C38,$F$11:$F$32) -> 0 | H38: Luz | I38: =SUMIF($I$11:$I$22,H38,$K$11:$K$22) -> 0
D39: =SUMIF($D$11:$D$32,C39,$F$11:$F$32) -> 0 | H39: Gasolina | I39: =SUMIF($I$11:$I$22,H39,$K$11:$K$22) -> 0
H40: Dizimos | I40: =SUMIF($I$11:$I$22,H40,$K$11:$K$22) -> 0
B41: Lazer | C41: Delivery (iFood, etc) | D41: =SUMIF($D$11:$D$32,C41,$F$11:$F$32) -> 0 | H41: Ofertas | I41: =SUMIF($I$11:$I$22,H41,$K$11:$K$22) -> 0
B42: =SUBTOTAL(9,D41:D48) -> 0 | C42: Cinema / Shows | D42: =SUMIF($D$11:$D$32,C42,$F$11:$F$32) -> 0 | H42: Parcelas | I42: =SUMIF($I$11:$I$22,H42,$K$11:$K$22) -> 0
C43: Passeios / Viagens | D43: =SUMIF($D$11:$D$32,C43,$F$11:$F$32) -> 0 | H43: Saúde | I43: =SUMIF($I$11:$I$22,H43,$K$11:$K$22) -> 0
C44: Compras por impulso (não essenciais) | D44: =SUMIF($D$11:$D$32,C44,$F$11:$F$32) -> 0 | H44: Investimento | I44: =SUMIF($I$11:$I$22,H44,$K$11:$K$22) -> 0
C45: Jogos / Games / Aplicativos pagos | D45: =SUMIF($D$11:$D$32,C45,$F$11:$F$32) -> 0 | I45: =SUMIF($I$11:$I$22,H45,$K$11:$K$22) -> 0
C46: Saídas com amigos | D46: =SUMIF($D$11:$D$32,C46,$F$11:$F$32) -> 0
D47: =SUMIF($D$11:$D$32,C47,$F$11:$F$32) -> 0
D48: =SUMIF($D$11:$D$32,C48,$F$11:$F$32) -> 0
B50: Despesas | C50: Presentes e datas comemorativas | D50: =SUMIF($D$11:$D$32,C50,$F$11:$F$32) -> 0
B51: =SUM(D50:D56) -> 0 | C51: Doações / Contribuições | D51: =SUMIF($D$11:$D$32,C51,$F$11:$F$32) -> 0
C52: Taxas bancárias / Pix por engano | D52: =SUMIF($D$11:$D$32,C52,$F$11:$F$32) -> 0
C53: Compras online aleatórias | D53: =SUMIF($D$11:$D$32,C53,$F$11:$F$32) -> 0
C54: Manutenção da casa (lâmpada, pilha, etc) | D54: =SUMIF($D$11:$D$32,C54,$F$11:$F$32) -> 0
C55: Gastos pessoais (roupas, acessórios) | D55: =SUMIF($D$11:$D$32,C55,$F$11:$F$32) -> 0
D56: =SUMIF($D$11:$D$32,C56,$F$11:$F$32) -> 0
B58: Transporte | C58: Acessório | D58: =SUMIF($D$11:$D$32,C58,$F$11:$F$32) -> 0
B59: =SUM(D58:D64) -> 0 | C59: Uber / Táxi | D59: =SUMIF($D$11:$D$32,C59,$F$11:$F$32) -> 0
C60: Ônibus / Metrô | D60: =SUMIF($D$11:$D$32,C60,$F$11:$F$32) -> 0
C61: Estacionamento | D61: =SUMIF($D$11:$D$32,C61,$F$11:$F$32) -> 0
C62: Manutenção (óleo, pneu, etc) | D62: =SUMIF($D$11:$D$32,C62,$F$11:$F$32) -> 0
C63: Multas / Documentação | D63: =SUMIF($D$11:$D$32,C63,$F$11:$F$32) -> 0
D64: =SUMIF($D$11:$D$32,C64,$F$11:$F$32) -> 0
B66: Educação | C66: Livros | D66: =SUMIF($D$11:$D$32,C66,$F$11:$F$32) -> 0
B67: =SUM(D66:D72) -> 0 | C67: Cursos online (Udemy, Alura, etc) | D67: =SUMIF($D$11:$D$32,C67,$F$11:$F$32) -> 0
C68: Material escolar / didático | D68: =SUMIF($D$11:$D$32,C68,$F$11:$F$32) -> 0
C69: Apostilas | D69: =SUMIF($D$11:$D$32,C69,$F$11:$F$32) -> 0
...

Sheet Mai
B2: MAI | C2: entradas | D2: valor | F2: Saldo mensal
B3: salário | F3: =SUM(D3,D5,D6,D7,D4) -> 0 | I3: data
B4: Fotografia | D4: =SUM(P10:P25) -> 0 | F4: =SUM(F11:F32) -> 0 | I4: =TODAY() -> 46002
B5: extra 2 | F5: =D4 -> 0 | I5: ultimo update
B6: extra 3 | F6: =SUM(K11:K22) -> 0 | I6: 45847
B7: Saldo | D7: =Abr!F7 -> 0 | F7: =F3-F4-F6 -> 0
B9: Variados | H9: Fixos | M9: Eventos | N9: Data | O9: Descrição | P9: Entradas
B10: data | C10: topico | D10: sub-tópico | E10: descrição | F10: valor | H10: data | I10: Topico | J10: sub-tópico | K10: valor
B35: Alimentação | C35: Doces | D35: =SUMIF($D$11:$D$32,C35,$F$11:$F$32) -> 0 | H35: Internet | I35: =SUMIF($I$11:$I$22,H35,$K$11:$K$22) -> 0
B36: =SUM(D35:D39) -> 0 | C36: Padaria | D36: =SUMIF($D$11:$D$32,C36,$F$11:$F$32) -> 0 | H36: Planos/assinaturas | I36: =SUMIF($I$11:$I$22,H36,$K$11:$K$22) -> 0
C37: Almoço fora | D37: =SUMIF($D$11:$D$32,C37,$F$11:$F$32) -> 0 | H37: Agua | I37: =SUMIF($I$11:$I$22,H37,$K$11:$K$22) -> 0
C38: Lanches / Snacks | D38: =SUMIF($D$11:$D$32,C38,$F$11:$F$32) -> 0 | H38: Luz | I38: =SUMIF($I$11:$I$22,H38,$K$11:$K$22) -> 0
D39: =SUMIF($D$11:$D$32,C39,$F$11:$F$32) -> 0 | H39: Gasolina | I39: =SUMIF($I$11:$I$22,H39,$K$11:$K$22) -> 0
H40: Dizimos | I40: =SUMIF($I$11:$I$22,H40,$K$11:$K$22) -> 0
B41: Lazer | C41: Delivery (iFood, etc) | D41: =SUMIF($D$11:$D$32,C41,$F$11:$F$32) -> 0 | H41: Ofertas | I41: =SUMIF($I$11:$I$22,H41,$K$11:$K$22) -> 0
B42: =SUBTOTAL(9,D41:D48) -> 0 | C42: Cinema / Shows | D42: =SUMIF($D$11:$D$32,C42,$F$11:$F$32) -> 0 | H42: Parcelas | I42: =SUMIF($I$11:$I$22,H42,$K$11:$K$22) -> 0
C43: Passeios / Viagens | D43: =SUMIF($D$11:$D$32,C43,$F$11:$F$32) -> 0 | H43: Saúde | I43: =SUMIF($I$11:$I$22,H43,$K$11:$K$22) -> 0
C44: Compras por impulso (não essenciais) | D44: =SUMIF($D$11:$D$32,C44,$F$11:$F$32) -> 0 | H44: Investimento | I44: =SUMIF($I$11:$I$22,H44,$K$11:$K$22) -> 0
C45: Jogos / Games / Aplicativos pagos | D45: =SUMIF($D$11:$D$32,C45,$F$11:$F$32) -> 0 | I45: =SUMIF($I$11:$I$22,H45,$K$11:$K$22) -> 0
C46: Saídas com amigos | D46: =SUMIF($D$11:$D$32,C46,$F$11:$F$32) -> 0
D47: =SUMIF($D$11:$D$32,C47,$F$11:$F$32) -> 0
D48: =SUMIF($D$11:$D$32,C48,$F$11:$F$32) -> 0
B50: Despesas | C50: Presentes e datas comemorativas | D50: =SUMIF($D$11:$D$32,C50,$F$11:$F$32) -> 0
B51: =SUM(D50:D56) -> 0 | C51: Doações / Contribuições | D51: =SUMIF($D$11:$D$32,C51,$F$11:$F$32) -> 0
C52: Taxas bancárias / Pix por engano | D52: =SUMIF($D$11:$D$32,C52,$F$11:$F$32) -> 0
C53: Compras online aleatórias | D53: =SUMIF($D$11:$D$32,C53,$F$11:$F$32) -> 0
C54: Manutenção da casa (lâmpada, pilha, etc) | D54: =SUMIF($D$11:$D$32,C54,$F$11:$F$32) -> 0
C55: Gastos pessoais (roupas, acessórios) | D55: =SUMIF($D$11:$D$32,C55,$F$11:$F$32) -> 0
D56: =SUMIF($D$11:$D$32,C56,$F$11:$F$32) -> 0
B58: Transporte | C58: Acessório | D58: =SUMIF($D$11:$D$32,C58,$F$11:$F$32) -> 0
B59: =SUM(D58:D64) -> 0 | C59: Uber / Táxi | D59: =SUMIF($D$11:$D$32,C59,$F$11:$F$32) -> 0
C60: Ônibus / Metrô | D60: =SUMIF($D$11:$D$32,C60,$F$11:$F$32) -> 0
C61: Estacionamento | D61: =SUMIF($D$11:$D$32,C61,$F$11:$F$32) -> 0
C62: Manutenção (óleo, pneu, etc) | D62: =SUMIF($D$11:$D$32,C62,$F$11:$F$32) -> 0
C63: Multas / Documentação | D63: =SUMIF($D$11:$D$32,C63,$F$11:$F$32) -> 0
D64: =SUMIF($D$11:$D$32,C64,$F$11:$F$32) -> 0
B66: Educação | C66: Livros | D66: =SUMIF($D$11:$D$32,C66,$F$11:$F$32) -> 0
B67: =SUM(D66:D72) -> 0 | C67: Cursos online (Udemy, Alura, etc) | D67: =SUMIF($D$11:$D$32,C67,$F$11:$F$32) -> 0
C68: Material escolar / didático | D68: =SUMIF($D$11:$D$32,C68,$F$11:$F$32) -> 0
C69: Apostilas | D69: =SUMIF($D$11:$D$32,C69,$F$11:$F$32) -> 0
...

Sheet Jun
B2: JUN | C2: entradas | D2: valor | F2: Saldo mensal
B3: salário | F3: =SUM(D3,D5,D6,D7,D4) -> 0 | I3: data
B4: Fotografia | D4: =SUM(P10:P25) -> 0 | F4: =SUM(F11:F32) -> 0 | I4: =TODAY() -> 46002
B5: extra 2 | F5: =D4 -> 0 | I5: ultimo update
B6: extra 3 | F6: =SUM(K11:K22) -> 0 | I6: 45847
B7: Saldo | D7: =Mai!F7 -> 0 | F7: =F3-F4-F6 -> 0
B9: Variados | H9: Fixos | M9: Eventos | N9: Data | O9: Descrição | P9: Entradas
B10: data | C10: topico | D10: sub-tópico | E10: descrição | F10: valor | H10: data | I10: Topico | J10: sub-tópico | K10: valor
B35: Alimentação | C35: Doces | D35: =SUMIF($D$11:$D$32,C35,$F$11:$F$32) -> 0 | H35: Internet | I35: =SUMIF($I$11:$I$22,H35,$K$11:$K$22) -> 0
B36: =SUM(D35:D39) -> 0 | C36: Padaria | D36: =SUMIF($D$11:$D$32,C36,$F$11:$F$32) -> 0 | H36: Planos/assinaturas | I36: =SUMIF($I$11:$I$22,H36,$K$11:$K$22) -> 0
C37: Almoço fora | D37: =SUMIF($D$11:$D$32,C37,$F$11:$F$32) -> 0 | H37: Agua | I37: =SUMIF($I$11:$I$22,H37,$K$11:$K$22) -> 0
C38: Lanches / Snacks | D38: =SUMIF($D$11:$D$32,C38,$F$11:$F$32) -> 0 | H38: Luz | I38: =SUMIF($I$11:$I$22,H38,$K$11:$K$22) -> 0
D39: =SUMIF($D$11:$D$32,C39,$F$11:$F$32) -> 0 | H39: Gasolina | I39: =SUMIF($I$11:$I$22,H39,$K$11:$K$22) -> 0
H40: Dizimos | I40: =SUMIF($I$11:$I$22,H40,$K$11:$K$22) -> 0
B41: Lazer | C41: Delivery (iFood, etc) | D41: =SUMIF($D$11:$D$32,C41,$F$11:$F$32) -> 0 | H41: Ofertas | I41: =SUMIF($I$11:$I$22,H41,$K$11:$K$22) -> 0
B42: =SUBTOTAL(9,D41:D48) -> 0 | C42: Cinema / Shows | D42: =SUMIF($D$11:$D$32,C42,$F$11:$F$32) -> 0 | H42: Parcelas | I42: =SUMIF($I$11:$I$22,H42,$K$11:$K$22) -> 0
C43: Passeios / Viagens | D43: =SUMIF($D$11:$D$32,C43,$F$11:$F$32) -> 0 | H43: Saúde | I43: =SUMIF($I$11:$I$22,H43,$K$11:$K$22) -> 0
C44: Compras por impulso (não essenciais) | D44: =SUMIF($D$11:$D$32,C44,$F$11:$F$32) -> 0 | H44: Investimento | I44: =SUMIF($I$11:$I$22,H44,$K$11:$K$22) -> 0
C45: Jogos / Games / Aplicativos pagos | D45: =SUMIF($D$11:$D$32,C45,$F$11:$F$32) -> 0 | I45: =SUMIF($I$11:$I$22,H45,$K$11:$K$22) -> 0
C46: Saídas com amigos | D46: =SUMIF($D$11:$D$32,C46,$F$11:$F$32) -> 0
D47: =SUMIF($D$11:$D$32,C47,$F$11:$F$32) -> 0
D48: =SUMIF($D$11:$D$32,C48,$F$11:$F$32) -> 0
B50: Despesas | C50: Presentes e datas comemorativas | D50: =SUMIF($D$11:$D$32,C50,$F$11:$F$32) -> 0
B51: =SUM(D50:D56) -> 0 | C51: Doações / Contribuições | D51: =SUMIF($D$11:$D$32,C51,$F$11:$F$32) -> 0
C52: Taxas bancárias / Pix por engano | D52: =SUMIF($D$11:$D$32,C52,$F$11:$F$32) -> 0
C53: Compras online aleatórias | D53: =SUMIF($D$11:$D$32,C53,$F$11:$F$32) -> 0
C54: Manutenção da casa (lâmpada, pilha, etc) | D54: =SUMIF($D$11:$D$32,C54,$F$11:$F$32) -> 0
C55: Gastos pessoais (roupas, acessórios) | D55: =SUMIF($D$11:$D$32,C55,$F$11:$F$32) -> 0
D56: =SUMIF($D$11:$D$32,C56,$F$11:$F$32) -> 0
B58: Transporte | C58: Acessório | D58: =SUMIF($D$11:$D$32,C58,$F$11:$F$32) -> 0
B59: =SUM(D58:D64) -> 0 | C59: Uber / Táxi | D59: =SUMIF($D$11:$D$32,C59,$F$11:$F$32) -> 0
C60: Ônibus / Metrô | D60: =SUMIF($D$11:$D$32,C60,$F$11:$F$32) -> 0
C61: Estacionamento | D61: =SUMIF($D$11:$D$32,C61,$F$11:$F$32) -> 0
C62: Manutenção (óleo, pneu, etc) | D62: =SUMIF($D$11:$D$32,C62,$F$11:$F$32) -> 0
C63: Multas / Documentação | D63: =SUMIF($D$11:$D$32,C63,$F$11:$F$32) -> 0
D64: =SUMIF($D$11:$D$32,C64,$F$11:$F$32) -> 0
B66: Educação | C66: Livros | D66: =SUMIF($D$11:$D$32,C66,$F$11:$F$32) -> 0
B67: =SUM(D66:D72) -> 0 | C67: Cursos online (Udemy, Alura, etc) | D67: =SUMIF($D$11:$D$32,C67,$F$11:$F$32) -> 0
C68: Material escolar / didático | D68: =SUMIF($D$11:$D$32,C68,$F$11:$F$32) -> 0
C69: Apostilas | D69: =SUMIF($D$11:$D$32,C69,$F$11:$F$32) -> 0
...

Sheet Jul
B2: JUL | C2: entradas | D2: valor | F2: Saldo mensal
B3: salário | D3: 654 | F3: =SUM(D3,D5,D6,D7,D4) -> 654 | I3: data
B4: Fotografia | D4: =SUM(P10:P25) -> 0 | F4: =SUM(F11:F32) -> 528 | I4: =TODAY() -> 46002
B5: extra 2 | F5: =D4 -> 0 | I5: ultimo update
B6: extra 3 | F6: =SUM(K11:K22) -> 0 | I6: 45847
B7: Saldo | D7: =Jun!F7 -> 0 | F7: =F3-F4-F6 -> 126
B9: Variados | H9: Fixos | M9: Eventos | N9: Data | O9: Descrição | P9: Entradas
B10: data | C10: topico | D10: sub-tópico | E10: descrição | F10: valor | H10: data | I10: Topico | J10: sub-tópico | K10: valor
B11: 45862 | C11: Lazer | D11: Cinema / Shows | E11: Ingresso par aProjeto Sola | F11: 57
B12: 45894 | C12: Transporte | D12: Multas / Documentação | E12: Moto pista | F12: 460
B13: 45688 | C13: Despesas | D13: Presentes e datas comemorativas | E13: Bolo de pote | F13: 11
B35: Alimentação | C35: Doces | D35: =SUMIF($D$11:$D$32,C35,$F$11:$F$32) -> 0 | H35: Internet | I35: =SUMIF($I$11:$I$22,H35,$K$11:$K$22) -> 0
B36: =SUM(D35:D39) -> 0 | C36: Padaria | D36: =SUMIF($D$11:$D$32,C36,$F$11:$F$32) -> 0 | H36: Planos/assinaturas | I36: =SUMIF($I$11:$I$22,H36,$K$11:$K$22) -> 0
C37: Almoço fora | D37: =SUMIF($D$11:$D$32,C37,$F$11:$F$32) -> 0 | H37: Agua | I37: =SUMIF($I$11:$I$22,H37,$K$11:$K$22) -> 0
C38: Lanches / Snacks | D38: =SUMIF($D$11:$D$32,C38,$F$11:$F$32) -> 0 | H38: Luz | I38: =SUMIF($I$11:$I$22,H38,$K$11:$K$22) -> 0
D39: =SUMIF($D$11:$D$32,C39,$F$11:$F$32) -> 0 | H39: Gasolina | I39: =SUMIF($I$11:$I$22,H39,$K$11:$K$22) -> 0
H40: Dizimos | I40: =SUMIF($I$11:$I$22,H40,$K$11:$K$22) -> 0
B41: Lazer | C41: Delivery (iFood, etc) | D41: =SUMIF($D$11:$D$32,C41,$F$11:$F$32) -> 0 | H41: Ofertas | I41: =SUMIF($I$11:$I$22,H41,$K$11:$K$22) -> 0
B42: =SUBTOTAL(9,D41:D48) -> 57 | C42: Cinema / Shows | D42: =SUMIF($D$11:$D$32,C42,$F$11:$F$32) -> 57 | H42: Parcelas | I42: =SUMIF($I$11:$I$22,H42,$K$11:$K$22) -> 0
C43: Passeios / Viagens | D43: =SUMIF($D$11:$D$32,C43,$F$11:$F$32) -> 0 | H43: Saúde | I43: =SUMIF($I$11:$I$22,H43,$K$11:$K$22) -> 0
C44: Compras por impulso (não essenciais) | D44: =SUMIF($D$11:$D$32,C44,$F$11:$F$32) -> 0 | H44: Investimento | I44: =SUMIF($I$11:$I$22,H44,$K$11:$K$22) -> 0
C45: Jogos / Games / Aplicativos pagos | D45: =SUMIF($D$11:$D$32,C45,$F$11:$F$32) -> 0 | I45: =SUMIF($I$11:$I$22,H45,$K$11:$K$22) -> 0
C46: Saídas com amigos | D46: =SUMIF($D$11:$D$32,C46,$F$11:$F$32) -> 0
D47: =SUMIF($D$11:$D$32,C47,$F$11:$F$32) -> 0
D48: =SUMIF($D$11:$D$32,C48,$F$11:$F$32) -> 0
B50: Despesas | C50: Presentes e datas comemorativas | D50: =SUMIF($D$11:$D$32,C50,$F$11:$F$32) -> 11
B51: =SUM(D50:D56) -> 11 | C51: Doações / Contribuições | D51: =SUMIF($D$11:$D$32,C51,$F$11:$F$32) -> 0
C52: Taxas bancárias / Pix por engano | D52: =SUMIF($D$11:$D$32,C52,$F$11:$F$32) -> 0
C53: Compras online aleatórias | D53: =SUMIF($D$11:$D$32,C53,$F$11:$F$32) -> 0
C54: Manutenção da casa (lâmpada, pilha, etc) | D54: =SUMIF($D$11:$D$32,C54,$F$11:$F$32) -> 0
C55: Gastos pessoais (roupas, acessórios) | D55: =SUMIF($D$11:$D$32,C55,$F$11:$F$32) -> 0
D56: =SUMIF($D$11:$D$32,C56,$F$11:$F$32) -> 0
B58: Transporte | C58: Acessório | D58: =SUMIF($D$11:$D$32,C58,$F$11:$F$32) -> 0
B59: =SUM(D58:D64) -> 460 | C59: Uber / Táxi | D59: =SUMIF($D$11:$D$32,C59,$F$11:$F$32) -> 0
C60: Ônibus / Metrô | D60: =SUMIF($D$11:$D$32,C60,$F$11:$F$32) -> 0
C61: Estacionamento | D61: =SUMIF($D$11:$D$32,C61,$F$11:$F$32) -> 0
C62: Manutenção (óleo, pneu, etc) | D62: =SUMIF($D$11:$D$32,C62,$F$11:$F$32) -> 0
C63: Multas / Documentação | D63: =SUMIF($D$11:$D$32,C63,$F$11:$F$32) -> 460
D64: =SUMIF($D$11:$D$32,C64,$F$11:$F$32) -> 0
B66: Educação | C66: Livros | D66: =SUMIF($D$11:$D$32,C66,$F$11:$F$32) -> 0
...

Sheet Ago
B2: AGO | C2: entradas | D2: valor | F2: Saldo mensal
B3: salário | D3: 659.52 | F3: =SUM(D3,D5,D6,D7,D4) -> 785.52 | I3: data
B4: Fotografia | C4: minha mãe me mandou 100 reias | D4: =SUM(P10:P25) -> 0 | F4: =SUM(F11:F32) -> 427.15 | I4: =TODAY() -> 46002
B5: extra 2 | F5: =D4 -> 0 | I5: ultimo update
B6: extra 3 | F6: =SUM(K11:K22) -> 220 | I6: 45879
B7: Saldo | D7: =Jul!F7 -> 126 | F7: =F3-F4-F6 -> 138.37
B9: Variados | H9: Fixos | M9: Eventos | N9: Data | O9: Descrição | P9: Entradas
B10: data | C10: topico | D10: sub-tópico | E10: descrição | F10: valor | H10: data | I10: Topico | J10: sub-tópico | K10: valor
B11: 45880 | C11: Transporte | D11: Uber / Táxi | E11: moto pista | F11: 5 | H11: 45876 | J11: plano internet claro | K11: 60
B12: 45879 | C12: Alimentação | D12: Lanches / Snacks | E12: Churrasco dia dos pais | F12: 27 | H12: 45876 | J12: Parcla de cell | K12: 130
B13: 45873 | C13: Transporte | D13: Uber / Táxi | E13: moto pista | F13: 5 | H13: 45899 | J13: corte de cabelo antes da festa | K13: 30
B14: 45880 | C14: Lazer | D14: Passeios / Viagens | E14: sitio mocidade | F14: 75
B15: 45881 | C15: Transporte | D15: Uber / Táxi | E15: moto pista | F15: 5
B16: 45882 | C16: Transporte | D16: Uber / Táxi | E16: moto pista | F16: 7
B17: 45882 | C17: Transporte | D17: Uber / Táxi | E17: senac | F17: 5.31
B18: 45883 | C18: Transporte | D18: Uber / Táxi | E18: moto pista | F18: 6.7
B19: 45883 | C19: Lazer | D19: Saídas com amigos | E19: bolo Iara | F19: 6.14
B20: 45884 | C20: Imprevistos | D20: Ajuda financeira a alguém (urgente) | E20: telhado | F20: 270
B21: 45885 | C21: Transporte | D21: Uber / Táxi | E21: moto pista | F21: 7.5
B22: 45886 | C22: Transporte | D22: Uber / Táxi | E22: moto pista | F22: 7.5
B35: Alimentação | C35: Doces | D35: =SUMIF($D$11:$D$32,C35,$F$11:$F$32) -> 0 | H35: Internet | I35: =SUMIF($I$11:$I$22,H35,$K$11:$K$22) -> 0
B36: =SUM(D35:D39) -> 27 | C36: Padaria | D36: =SUMIF($D$11:$D$32,C36,$F$11:$F$32) -> 0 | H36: Planos/assinaturas | I36: =SUMIF($I$11:$I$22,H36,$K$11:$K$22) -> 0
C37: Almoço fora | D37: =SUMIF($D$11:$D$32,C37,$F$11:$F$32) -> 0 | H37: Agua | I37: =SUMIF($I$11:$I$22,H37,$K$11:$K$22) -> 0
C38: Lanches / Snacks | D38: =SUMIF($D$11:$D$32,C38,$F$11:$F$32) -> 27 | H38: Luz | I38: =SUMIF($I$11:$I$22,H38,$K$11:$K$22) -> 0
D39: =SUMIF($D$11:$D$32,C39,$F$11:$F$32) -> 0 | H39: Gasolina | I39: =SUMIF($I$11:$I$22,H39,$K$11:$K$22) -> 0
H40: Dizimos | I40: =SUMIF($I$11:$I$22,H40,$K$11:$K$22) -> 0
B41: Lazer | C41: Delivery (iFood, etc) | D41: =SUMIF($D$11:$D$32,C41,$F$11:$F$32) -> 0 | H41: Ofertas | I41: =SUMIF($I$11:$I$22,H41,$K$11:$K$22) -> 0
B42: =SUBTOTAL(9,D41:D48) -> 81.14 | C42: Cinema / Shows | D42: =SUMIF($D$11:$D$32,C42,$F$11:$F$32) -> 0 | H42: Parcelas | I42: =SUMIF($I$11:$I$22,H42,$K$11:$K$22) -> 0
C43: Passeios / Viagens | D43: =SUMIF($D$11:$D$32,C43,$F$11:$F$32) -> 75 | H43: Saúde | I43: =SUMIF($I$11:$I$22,H43,$K$11:$K$22) -> 0
C44: Compras por impulso (não essenciais) | D44: =SUMIF($D$11:$D$32,C44,$F$11:$F$32) -> 0 | H44: Investimento | I44: =SUMIF($I$11:$I$22,H44,$K$11:$K$22) -> 0
C45: Jogos / Games / Aplicativos pagos | D45: =SUMIF($D$11:$D$32,C45,$F$11:$F$32) -> 0 | I45: =SUMIF($I$11:$I$22,H45,$K$11:$K$22) -> 0
C46: Saídas com amigos | D46: =SUMIF($D$11:$D$32,C46,$F$11:$F$32) -> 6.14
D47: =SUMIF($D$11:$D$32,C47,$F$11:$F$32) -> 0
D48: =SUMIF($D$11:$D$32,C48,$F$11:$F$32) -> 0
B50: Despesas | C50: Presentes e datas comemorativas | D50: =SUMIF($D$11:$D$32,C50,$F$11:$F$32) -> 0
B51: =SUM(D50:D56) -> 0 | C51: Doações / Contribuições | D51: =SUMIF($D$11:$D$32,C51,$F$11:$F$32) -> 0
C52: Taxas bancárias / Pix por engano | D52: =SUMIF($D$11:$D$32,C52,$F$11:$F$32) -> 0
C53: Compras online aleatórias | D53: =SUMIF($D$11:$D$32,C53,$F$11:$F$32) -> 0
C54: Manutenção da casa (lâmpada, pilha, etc) | D54: =SUMIF($D$11:$D$32,C54,$F$11:$F$32) -> 0
C55: Gastos pessoais (roupas, acessórios) | D55: =SUMIF($D$11:$D$32,C55,$F$11:$F$32) -> 0
...

Sheet Set
B2: SET | C2: entradas | D2: valor | F2: Saldo mensal
B3: salário | D3: 659.52 | F3: =SUM(D3,D5,D6,D7,D4) -> 797.89 | I3: data
B4: Fotografia | D4: =SUM(P10:P25) -> 0 | F4: =SUM(F11:F32) -> 177.39 | I4: =TODAY() -> 46002
B5: extra 2 | F5: =D4 -> 0 | I5: ultimo update
B6: extra 3 | F6: =SUM(K11:K22) -> 283.8 | I6: 45847
B7: Saldo | D7: =Ago!F7 -> 138.37 | F7: =F3-F4-F6 -> 336.7
B9: Variados | H9: Fixos | M9: Eventos | N9: Data | O9: Descrição | P9: Entradas
B10: data | C10: topico | D10: sub-tópico | E10: descrição | F10: valor | H10: data | I10: Topico | J10: sub-tópico | K10: valor
B11: 45901 | C11: Transporte | D11: Uber / Táxi | E11: curso | F11: 5.5 | H11: 45901 | I11: Parcelas | J11: cell, camera | K11: 277
B12: 45903 | C12: Despesas | D12: Compras online aleatórias | E12: cartão de memória e adaptador | F12: 85.29 | H12: 45906 | I12: Planos/assinaturas | J12: spotify | K12: 6.8
B13: 45903 | C13: Alimentação | D13: Lanches / Snacks | E13: biscoito | F13: 1.6
B14: 1209 | C14: Despesas | D14: Presentes e datas comemorativas | E14: fone - Marcelles e PH | F14: 75
B15: 45918 | C15: Lazer | D15: Saídas com amigos | E15: Igreja - evento | F15: 10
B35: Alimentação | C35: Doces | D35: =SUMIF($D$11:$D$32,C35,$F$11:$F$32) -> 0 | H35: Internet | I35: =SUMIF($I$11:$I$22,H35,$K$11:$K$22) -> 0
B36: =SUM(D35:D39) -> 1.6 | C36: Padaria | D36: =SUMIF($D$11:$D$32,C36,$F$11:$F$32) -> 0 | H36: Planos/assinaturas | I36: =SUMIF($I$11:$I$22,H36,$K$11:$K$22) -> 6.8
C37: Almoço fora | D37: =SUMIF($D$11:$D$32,C37,$F$11:$F$32) -> 0 | H37: Agua | I37: =SUMIF($I$11:$I$22,H37,$K$11:$K$22) -> 0
C38: Lanches / Snacks | D38: =SUMIF($D$11:$D$32,C38,$F$11:$F$32) -> 1.6 | H38: Luz | I38: =SUMIF($I$11:$I$22,H38,$K$11:$K$22) -> 0
D39: =SUMIF($D$11:$D$32,C39,$F$11:$F$32) -> 0 | H39: Gasolina | I39: =SUMIF($I$11:$I$22,H39,$K$11:$K$22) -> 0
H40: Dizimos | I40: =SUMIF($I$11:$I$22,H40,$K$11:$K$22) -> 0
B41: Lazer | C41: Delivery (iFood, etc) | D41: =SUMIF($D$11:$D$32,C41,$F$11:$F$32) -> 0 | H41: Ofertas | I41: =SUMIF($I$11:$I$22,H41,$K$11:$K$22) -> 0
B42: =SUBTOTAL(9,D41:D48) -> 10 | C42: Cinema / Shows | D42: =SUMIF($D$11:$D$32,C42,$F$11:$F$32) -> 0 | H42: Parcelas | I42: =SUMIF($I$11:$I$22,H42,$K$11:$K$22) -> 277
C43: Passeios / Viagens | D43: =SUMIF($D$11:$D$32,C43,$F$11:$F$32) -> 0 | H43: Saúde | I43: =SUMIF($I$11:$I$22,H43,$K$11:$K$22) -> 0
C44: Compras por impulso (não essenciais) | D44: =SUMIF($D$11:$D$32,C44,$F$11:$F$32) -> 0 | H44: Investimento | I44: =SUMIF($I$11:$I$22,H44,$K$11:$K$22) -> 0
C45: Jogos / Games / Aplicativos pagos | D45: =SUMIF($D$11:$D$32,C45,$F$11:$F$32) -> 0 | I45: =SUMIF($I$11:$I$22,H45,$K$11:$K$22) -> 0
C46: Saídas com amigos | D46: =SUMIF($D$11:$D$32,C46,$F$11:$F$32) -> 10
D47: =SUMIF($D$11:$D$32,C47,$F$11:$F$32) -> 0
D48: =SUMIF($D$11:$D$32,C48,$F$11:$F$32) -> 0
B50: Despesas | C50: Presentes e datas comemorativas | D50: =SUMIF($D$11:$D$32,C50,$F$11:$F$32) -> 75
B51: =SUM(D50:D56) -> 160.29 | C51: Doações / Contribuições | D51: =SUMIF($D$11:$D$32,C51,$F$11:$F$32) -> 0
C52: Taxas bancárias / Pix por engano | D52: =SUMIF($D$11:$D$32,C52,$F$11:$F$32) -> 0
C53: Compras online aleatórias | D53: =SUMIF($D$11:$D$32,C53,$F$11:$F$32) -> 85.29
C54: Manutenção da casa (lâmpada, pilha, etc) | D54: =SUMIF($D$11:$D$32,C54,$F$11:$F$32) -> 0
C55: Gastos pessoais (roupas, acessórios) | D55: =SUMIF($D$11:$D$32,C55,$F$11:$F$32) -> 0
D56: =SUMIF($D$11:$D$32,C56,$F$11:$F$32) -> 0
B58: Transporte | C58: Acessório | D58: =SUMIF($D$11:$D$32,C58,$F$11:$F$32) -> 0
B59: =SUM(D58:D64) -> 5.5 | C59: Uber / Táxi | D59: =SUMIF($D$11:$D$32,C59,$F$11:$F$32) -> 5.5
C60: Ônibus / Metrô | D60: =SUMIF($D$11:$D$32,C60,$F$11:$F$32) -> 0
C61: Estacionamento | D61: =SUMIF($D$11:$D$32,C61,$F$11:$F$32) -> 0
C62: Manutenção (óleo, pneu, etc) | D62: =SUMIF($D$11:$D$32,C62,$F$11:$F$32) -> 0
C63: Multas / Documentação | D63: =SUMIF($D$11:$D$32,C63,$F$11:$F$32) -> 0
...

Sheet Out
B2: OUT | C2: entradas | D2: valor | F2: Saldo mensal
B3: salário | F3: =SUM(D3,D5,D6,D7,D4) -> 336.7 | I3: data
B4: Fotografia | D4: =SUM(P10:P25) -> 0 | F4: =SUM(F11:F32) -> 63.8 | I4: =TODAY() -> 46002
B5: extra 2 | F5: =D4 -> 0 | I5: ultimo update
B6: extra 3 | F6: =SUM(K11:K22) -> 0 | I6: 45847
B7: Saldo | D7: =Set!F7 -> 336.7 | F7: =F3-F4-F6 -> 272.9
B9: Variados | H9: Fixos | M9: Eventos | N9: Data | O9: Descrição | P9: Entradas
B10: data | C10: topico | D10: sub-tópico | E10: descrição | F10: valor | H10: data | I10: Topico | J10: sub-tópico | K10: valor
B11: 30 | C11: Despesas | D11: Gastos pessoais (roupas, acessórios) | E11: camera | F11: 63.8
B35: Alimentação | C35: Doces | D35: =SUMIF($D$11:$D$32,C35,$F$11:$F$32) -> 0 | H35: Internet | I35: =SUMIF($I$11:$I$22,H35,$K$11:$K$22) -> 0
B36: =SUM(D35:D39) -> 0 | C36: Padaria | D36: =SUMIF($D$11:$D$32,C36,$F$11:$F$32) -> 0 | H36: Planos/assinaturas | I36: =SUMIF($I$11:$I$22,H36,$K$11:$K$22) -> 0
C37: Almoço fora | D37: =SUMIF($D$11:$D$32,C37,$F$11:$F$32) -> 0 | H37: Agua | I37: =SUMIF($I$11:$I$22,H37,$K$11:$K$22) -> 0
C38: Lanches / Snacks | D38: =SUMIF($D$11:$D$32,C38,$F$11:$F$32) -> 0 | H38: Luz | I38: =SUMIF($I$11:$I$22,H38,$K$11:$K$22) -> 0
D39: =SUMIF($D$11:$D$32,C39,$F$11:$F$32) -> 0 | H39: Gasolina | I39: =SUMIF($I$11:$I$22,H39,$K$11:$K$22) -> 0
H40: Dizimos | I40: =SUMIF($I$11:$I$22,H40,$K$11:$K$22) -> 0
B41: Lazer | C41: Delivery (iFood, etc) | D41: =SUMIF($D$11:$D$32,C41,$F$11:$F$32) -> 0 | H41: Ofertas | I41: =SUMIF($I$11:$I$22,H41,$K$11:$K$22) -> 0
B42: =SUBTOTAL(9,D41:D48) -> 0 | C42: Cinema / Shows | D42: =SUMIF($D$11:$D$32,C42,$F$11:$F$32) -> 0 | H42: Parcelas | I42: =SUMIF($I$11:$I$22,H42,$K$11:$K$22) -> 0
C43: Passeios / Viagens | D43: =SUMIF($D$11:$D$32,C43,$F$11:$F$32) -> 0 | H43: Saúde | I43: =SUMIF($I$11:$I$22,H43,$K$11:$K$22) -> 0
C44: Compras por impulso (não essenciais) | D44: =SUMIF($D$11:$D$32,C44,$F$11:$F$32) -> 0 | H44: Investimento | I44: =SUMIF($I$11:$I$22,H44,$K$11:$K$22) -> 0
C45: Jogos / Games / Aplicativos pagos | D45: =SUMIF($D$11:$D$32,C45,$F$11:$F$32) -> 0 | I45: =SUMIF($I$11:$I$22,H45,$K$11:$K$22) -> 0
C46: Saídas com amigos | D46: =SUMIF($D$11:$D$32,C46,$F$11:$F$32) -> 0
D47: =SUMIF($D$11:$D$32,C47,$F$11:$F$32) -> 0
D48: =SUMIF($D$11:$D$32,C48,$F$11:$F$32) -> 0
B50: Despesas | C50: Presentes e datas comemorativas | D50: =SUMIF($D$11:$D$32,C50,$F$11:$F$32) -> 0
B51: =SUM(D50:D56) -> 63.8 | C51: Doações / Contribuições | D51: =SUMIF($D$11:$D$32,C51,$F$11:$F$32) -> 0
C52: Taxas bancárias / Pix por engano | D52: =SUMIF($D$11:$D$32,C52,$F$11:$F$32) -> 0
C53: Compras online aleatórias | D53: =SUMIF($D$11:$D$32,C53,$F$11:$F$32) -> 0
C54: Manutenção da casa (lâmpada, pilha, etc) | D54: =SUMIF($D$11:$D$32,C54,$F$11:$F$32) -> 0
C55: Gastos pessoais (roupas, acessórios) | D55: =SUMIF($D$11:$D$32,C55,$F$11:$F$32) -> 63.8
D56: =SUMIF($D$11:$D$32,C56,$F$11:$F$32) -> 0
B58: Transporte | C58: Acessório | D58: =SUMIF($D$11:$D$32,C58,$F$11:$F$32) -> 0
B59: =SUM(D58:D64) -> 0 | C59: Uber / Táxi | D59: =SUMIF($D$11:$D$32,C59,$F$11:$F$32) -> 0
C60: Ônibus / Metrô | D60: =SUMIF($D$11:$D$32,C60,$F$11:$F$32) -> 0
C61: Estacionamento | D61: =SUMIF($D$11:$D$32,C61,$F$11:$F$32) -> 0
C62: Manutenção (óleo, pneu, etc) | D62: =SUMIF($D$11:$D$32,C62,$F$11:$F$32) -> 0
C63: Multas / Documentação | D63: =SUMIF($D$11:$D$32,C63,$F$11:$F$32) -> 0
D64: =SUMIF($D$11:$D$32,C64,$F$11:$F$32) -> 0
B66: Educação | C66: Livros | D66: =SUMIF($D$11:$D$32,C66,$F$11:$F$32) -> 0
B67: =SUM(D66:D72) -> 0 | C67: Cursos online (Udemy, Alura, etc) | D67: =SUMIF($D$11:$D$32,C67,$F$11:$F$32) -> 0
C68: Material escolar / didático | D68: =SUMIF($D$11:$D$32,C68,$F$11:$F$32) -> 0
...

Sheet Nov
B2: NOV | C2: entradas | D2: valor | F2: Saldo mensal
B3: salário | F3: =SUM(D3,D5,D6,D7,D4) -> 272.9 | I3: data
B4: Fotografia | D4: =SUM(P10:P25) -> 0 | F4: =SUM(F11:F32) -> 322.9 | I4: =TODAY() -> 46002
B5: extra 2 | F5: =D4 -> 0 | I5: ultimo update
B6: extra 3 | F6: =SUM(K11:K22) -> 0 | I6: 45847
B7: Saldo | D7: =Out!F7 -> 272.9 | F7: =F3-F4-F6 -> -50
B9: Variados | H9: Fixos | M9: Eventos | N9: Data | O9: Descrição | P9: Entradas
B10: data | C10: topico | D10: sub-tópico | E10: descrição | F10: valor | H10: data | I10: Topico | J10: sub-tópico | K10: valor
F11: 272.9
F12: 50
B35: Alimentação | C35: Doces | D35: =SUMIF($D$11:$D$32,C35,$F$11:$F$32) -> 0 | H35: Internet | I35: =SUMIF($I$11:$I$22,H35,$K$11:$K$22) -> 0
B36: =SUM(D35:D39) -> 0 | C36: Padaria | D36: =SUMIF($D$11:$D$32,C36,$F$11:$F$32) -> 0 | H36: Planos/assinaturas | I36: =SUMIF($I$11:$I$22,H36,$K$11:$K$22) -> 0
C37: Almoço fora | D37: =SUMIF($D$11:$D$32,C37,$F$11:$F$32) -> 0 | H37: Agua | I37: =SUMIF($I$11:$I$22,H37,$K$11:$K$22) -> 0
C38: Lanches / Snacks | D38: =SUMIF($D$11:$D$32,C38,$F$11:$F$32) -> 0 | H38: Luz | I38: =SUMIF($I$11:$I$22,H38,$K$11:$K$22) -> 0
D39: =SUMIF($D$11:$D$32,C39,$F$11:$F$32) -> 0 | H39: Gasolina | I39: =SUMIF($I$11:$I$22,H39,$K$11:$K$22) -> 0
H40: Dizimos | I40: =SUMIF($I$11:$I$22,H40,$K$11:$K$22) -> 0
B41: Lazer | C41: Delivery (iFood, etc) | D41: =SUMIF($D$11:$D$32,C41,$F$11:$F$32) -> 0 | H41: Ofertas | I41: =SUMIF($I$11:$I$22,H41,$K$11:$K$22) -> 0
B42: =SUBTOTAL(9,D41:D48) -> 0 | C42: Cinema / Shows | D42: =SUMIF($D$11:$D$32,C42,$F$11:$F$32) -> 0 | H42: Parcelas | I42: =SUMIF($I$11:$I$22,H42,$K$11:$K$22) -> 0
C43: Passeios / Viagens | D43: =SUMIF($D$11:$D$32,C43,$F$11:$F$32) -> 0 | H43: Saúde | I43: =SUMIF($I$11:$I$22,H43,$K$11:$K$22) -> 0
C44: Compras por impulso (não essenciais) | D44: =SUMIF($D$11:$D$32,C44,$F$11:$F$32) -> 0 | H44: Investimento | I44: =SUMIF($I$11:$I$22,H44,$K$11:$K$22) -> 0
C45: Jogos / Games / Aplicativos pagos | D45: =SUMIF($D$11:$D$32,C45,$F$11:$F$32) -> 0 | I45: =SUMIF($I$11:$I$22,H45,$K$11:$K$22) -> 0
C46: Saídas com amigos | D46: =SUMIF($D$11:$D$32,C46,$F$11:$F$32) -> 0
D47: =SUMIF($D$11:$D$32,C47,$F$11:$F$32) -> 0
D48: =SUMIF($D$11:$D$32,C48,$F$11:$F$32) -> 0
B50: Despesas | C50: Presentes e datas comemorativas | D50: =SUMIF($D$11:$D$32,C50,$F$11:$F$32) -> 0
B51: =SUM(D50:D56) -> 0 | C51: Doações / Contribuições | D51: =SUMIF($D$11:$D$32,C51,$F$11:$F$32) -> 0
C52: Taxas bancárias / Pix por engano | D52: =SUMIF($D$11:$D$32,C52,$F$11:$F$32) -> 0
C53: Compras online aleatórias | D53: =SUMIF($D$11:$D$32,C53,$F$11:$F$32) -> 0
C54: Manutenção da casa (lâmpada, pilha, etc) | D54: =SUMIF($D$11:$D$32,C54,$F$11:$F$32) -> 0
C55: Gastos pessoais (roupas, acessórios) | D55: =SUMIF($D$11:$D$32,C55,$F$11:$F$32) -> 0
D56: =SUMIF($D$11:$D$32,C56,$F$11:$F$32) -> 0
B58: Transporte | C58: Acessório | D58: =SUMIF($D$11:$D$32,C58,$F$11:$F$32) -> 0
B59: =SUM(D58:D64) -> 0 | C59: Uber / Táxi | D59: =SUMIF($D$11:$D$32,C59,$F$11:$F$32) -> 0
C60: Ônibus / Metrô | D60: =SUMIF($D$11:$D$32,C60,$F$11:$F$32) -> 0
C61: Estacionamento | D61: =SUMIF($D$11:$D$32,C61,$F$11:$F$32) -> 0
C62: Manutenção (óleo, pneu, etc) | D62: =SUMIF($D$11:$D$32,C62,$F$11:$F$32) -> 0
C63: Multas / Documentação | D63: =SUMIF($D$11:$D$32,C63,$F$11:$F$32) -> 0
D64: =SUMIF($D$11:$D$32,C64,$F$11:$F$32) -> 0
B66: Educação | C66: Livros | D66: =SUMIF($D$11:$D$32,C66,$F$11:$F$32) -> 0
B67: =SUM(D66:D72) -> 0 | C67: Cursos online (Udemy, Alura, etc) | D67: =SUMIF($D$11:$D$32,C67,$F$11:$F$32) -> 0
...

Sheet Dez
B2: DEZ | C2: entradas | D2: valor | F2: Saldo mensal
B3: salário | D3: 652.59 | F3: =SUM(D3,D5,D6,D7,D4) -> 766.59 | I3: data
B4: Fotografia | D4: =SUM(P10:P25) -> 0 | F4: =SUM(F11:F32) -> 152.46 | I4: =TODAY() -> 46002
B5: extra 2 | D5: 84 | F5: =D4 -> 0 | I5: ultimo update
B6: extra 3 | D6: 80 | F6: =SUM(K11:K22) -> 414.3 | I6: 46002
B7: Saldo | D7: =Nov!F7 -> -50 | F7: =F3-F4-F6 -> 199.83
B9: Variados | H9: Fixos | M9: Eventos | N9: Data | O9: Descrição | P9: Entradas
B10: data | C10: topico | D10: sub-tópico | E10: descrição | F10: valor | H10: data | I10: Topico | J10: sub-tópico | K10: valor
B11: 46001 | C11: Alimentação | D11: Doces | E11: caixa de bombom | F11: 14.98 | H11: 1 | I11: Internet | J11: claro | K11: 30
B12: 46002 | C12: Despesas | D12: Manutenção da casa (lâmpada, pilha, etc) | E12: caixa para camera | F12: 22.5 | H12: 45966 | I12: Planos/assinaturas | J12: spotify | K12: 6.8
B13: 46002 | C13: Despesas | D13: Compras online aleatórias | E13: tripe e led | F13: 114.98 | H13: 45996 | I13: Parcelas | J13: ultima do cell | K13: 130
H14: 45998 | I14: Parcelas | J14: camera | K14: 147.5
H15: 45999 | I15: Parcelas | J15: sitio carnaval | K15: 70
H16: 46000 | I16: Gasolina | J16: moto | K16: 30
B35: Alimentação | C35: Doces | D35: =SUMIF($D$11:$D$32,C35,$F$11:$F$32) -> 14.98 | H35: Internet | I35: =SUMIF($I$11:$I$22,H35,$K$11:$K$22) -> 30
B36: =SUM(D35:D39) -> 14.98 | C36: Padaria | D36: =SUMIF($D$11:$D$32,C36,$F$11:$F$32) -> 0 | H36: Planos/assinaturas | I36: =SUMIF($I$11:$I$22,H36,$K$11:$K$22) -> 6.8
C37: Almoço fora | D37: =SUMIF($D$11:$D$32,C37,$F$11:$F$32) -> 0 | H37: Agua | I37: =SUMIF($I$11:$I$22,H37,$K$11:$K$22) -> 0
C38: Lanches / Snacks | D38: =SUMIF($D$11:$D$32,C38,$F$11:$F$32) -> 0 | H38: Luz | I38: =SUMIF($I$11:$I$22,H38,$K$11:$K$22) -> 0
D39: =SUMIF($D$11:$D$32,C39,$F$11:$F$32) -> 0 | H39: Gasolina | I39: =SUMIF($I$11:$I$22,H39,$K$11:$K$22) -> 30
H40: Dizimos | I40: =SUMIF($I$11:$I$22,H40,$K$11:$K$22) -> 0
B41: Lazer | C41: Delivery (iFood, etc) | D41: =SUMIF($D$11:$D$32,C41,$F$11:$F$32) -> 0 | H41: Ofertas | I41: =SUMIF($I$11:$I$22,H41,$K$11:$K$22) -> 0
B42: =SUBTOTAL(9,D41:D48) -> 0 | C42: Cinema / Shows | D42: =SUMIF($D$11:$D$32,C42,$F$11:$F$32) -> 0 | H42: Parcelas | I42: =SUMIF($I$11:$I$22,H42,$K$11:$K$22) -> 347.5
C43: Passeios / Viagens | D43: =SUMIF($D$11:$D$32,C43,$F$11:$F$32) -> 0 | H43: Saúde | I43: =SUMIF($I$11:$I$22,H43,$K$11:$K$22) -> 0
C44: Compras por impulso (não essenciais) | D44: =SUMIF($D$11:$D$32,C44,$F$11:$F$32) -> 0 | H44: Investimento | I44: =SUMIF($I$11:$I$22,H44,$K$11:$K$22) -> 0
C45: Jogos / Games / Aplicativos pagos | D45: =SUMIF($D$11:$D$32,C45,$F$11:$F$32) -> 0 | I45: =SUMIF($I$11:$I$22,H45,$K$11:$K$22) -> 0
C46: Saídas com amigos | D46: =SUMIF($D$11:$D$32,C46,$F$11:$F$32) -> 0
D47: =SUMIF($D$11:$D$32,C47,$F$11:$F$32) -> 0
D48: =SUMIF($D$11:$D$32,C48,$F$11:$F$32) -> 0
B50: Despesas | C50: Presentes e datas comemorativas | D50: =SUMIF($D$11:$D$32,C50,$F$11:$F$32) -> 0
B51: =SUM(D50:D56) -> 137.48 | C51: Doações / Contribuições | D51: =SUMIF($D$11:$D$32,C51,$F$11:$F$32) -> 0
C52: Taxas bancárias / Pix por engano | D52: =SUMIF($D$11:$D$32,C52,$F$11:$F$32) -> 0
C53: Compras online aleatórias | D53: =SUMIF($D$11:$D$32,C53,$F$11:$F$32) -> 114.98
C54: Manutenção da casa (lâmpada, pilha, etc) | D54: =SUMIF($D$11:$D$32,C54,$F$11:$F$32) -> 22.5
C55: Gastos pessoais (roupas, acessórios) | D55: =SUMIF($D$11:$D$32,C55,$F$11:$F$32) -> 0
D56: =SUMIF($D$11:$D$32,C56,$F$11:$F$32) -> 0
B58: Transporte | C58: Acessório | D58: =SUMIF($D$11:$D$32,C58,$F$11:$F$32) -> 0
B59: =SUM(D58:D64) -> 0 | C59: Uber / Táxi | D59: =SUMIF($D$11:$D$32,C59,$F$11:$F$32) -> 0
C60: Ônibus / Metrô | D60: =SUMIF($D$11:$D$32,C60,$F$11:$F$32) -> 0
C61: Estacionamento | D61: =SUMIF($D$11:$D$32,C61,$F$11:$F$32) -> 0
C62: Manutenção (óleo, pneu, etc) | D62: =SUMIF($D$11:$D$32,C62,$F$11:$F$32) -> 0
...

Sheet Anual
B2: SUB-TOTAIS | C2: Jan | D2: Fev | E2: Mar | F2: Abr | G2: Mai | H2: Jun | I2: Jul | J2: Ago | K2: Set | L2: Out | M2: Nov | N2: Dez | O2: total
B3: Entradas | C3: =Jan!$F$3 -> 0 | D3: =Fev!$F$3 -> 0 | E3: =Mar!$F$3 -> 0 | F3: =Abr!$F$3 -> 0 | G3: =Mai!$F$3 -> 0 | H3: =Jun!$F$3 -> 0 | I3: =Jul!$F$3 -> 654 | J3: =Ago!$F$3 -> 785.52 | K3: =Set!$F$3 -> 797.89 | L3: =Out!$F$3 -> 336.7 | M3: =Nov!$F$3 -> 272.9 | N3: =Dez!$F$3 -> 766.59 | O3: =SUM(C3:N3) -> 3613.6
B4: Saidas Variáveis | C4: =Jan!$F$4 -> 0 | D4: =Fev!$F$4 -> 0 | E4: =Mar!$F$4 -> 0 | F4: =Abr!$F$4 -> 0 | G4: =Mai!$F$4 -> 0 | H4: =Jun!$F$4 -> 0 | I4: =Jul!$F$4 -> 528 | J4: =Ago!$F$4 -> 427.15 | K4: =Set!$F$4 -> 177.39 | L4: =Out!$F$4 -> 63.8 | M4: =Nov!$F$4 -> 322.9 | N4: =Dez!$F$4 -> 152.46 | O4: =SUM(C4:N4) -> 1671.7
B5: Saidas Fixas | C5: =Jan!$F$6 -> 0 | D5: =Fev!$F$6 -> 0 | E5: =Mar!$F$6 -> 0 | F5: =Abr!$F$6 -> 0 | G5: =Mai!$F$6 -> 0 | H5: =Jun!$F$6 -> 0 | I5: =Jul!$F$6 -> 0 | J5: =Ago!$F$6 -> 220 | K5: =Set!$F$6 -> 283.8 | L5: =Out!$F$6 -> 0 | M5: =Nov!$F$6 -> 0 | N5: =Dez!$F$6 -> 414.3 | O5: =SUM(C5:N5) -> 918.1
B6: Saidas Totais | C6: =C4+C5 -> 0 | D6: =D4+D5 -> 0 | E6: =E4+E5 -> 0 | F6: =F4+F5 -> 0 | G6: =G4+G5 -> 0 | H6: =H4+H5 -> 0 | I6: =I4+I5 -> 528 | J6: =J4+J5 -> 647.15 | ... N6: =N4+N5 -> 566.76 | O6: =SUM(C6:N6) -> 2589.8
B7: Saldo | C7: =C3-C6 -> 0 | D7: =D3-D6 -> 0 | E7: =E3-E6 -> 0 | F7: =F3-F6 -> 0 | G7: =G3-G6 -> 0 | H7: =H3-H6 -> 0 | I7: =I3-I6 -> 126 | J7: =J3-J6 -> 138.37 | ... N7: =N3-N6 -> 199.83 | O7: =SUM(C7:N7) -> 1023.8
B8: Fotografia | C8: =Jan!D4 -> 0 | D8: =Fev!D4 -> 0 | E8: =Mar!D4 -> 0 | F8: =Abr!D4 -> 0 | G8: =Mai!D4 -> 0 | H8: =Jun!D4 -> 0 | I8: =Jul!D4 -> 0 | J8: =Ago!D4 -> 0 | K8: =Set!D4 -> 0 | L8: =Out!D4 -> 0 | M8: =Nov!D4 -> 0 | N8: =Dez!D4 -> 0 | O8: =SUM(C8:N8) -> 0
B13: SUB-TOTAIS | C13: Jan | D13: Fev | E13: Mar | F13: Abr | G13: Mai | H13: Jun | I13: Jul | J13: Ago | K13: Set | L13: Out | M13: Nov | N13: Dez | O13: TOTAL
B14: Alimentação | C14: =Jan!$B$36 -> 0 | D14: =Fev!$B$36 -> 0 | E14: =Jan!$B$36 -> 0 | F14: =Jan!$B$36 -> 0 | G14: =Jan!$B$36 -> 0 | H14: =Jan!$B$36 -> 0 | I14: =Jan!$B$36 -> 0 | J14: =Jan!$B$36 -> 0 | K14: =Jan!$B$36 -> 0 | L14: =Jan!$B$36 -> 0 | ... N14: =Jan!$B$36 -> 0 | O14: =SUM(C14:N14) -> 0
B15: Lazer | C15: =Fev!$B$42 -> 0 | D15: =Fev!$B$42 -> 0 | E15: =Fev!$B$42 -> 0 | F15: =Fev!$B$42 -> 0 | G15: =Fev!$B$42 -> 0 | H15: =Fev!$B$42 -> 0 | I15: =Fev!$B$42 -> 0 | J15: =Fev!$B$42 -> 0 | ... N15: =Fev!$B$42 -> 0 | O15: =SUM(C15:N15) -> 0
B16: Despesas | C16: =Jan!$B$51 -> 0 | D16: =Fev!B51 -> 0 | E16: =Jan!$B$51 -> 0 | F16: =Jan!$B$51 -> 0 | G16: =Jan!$B$51 -> 0 | H16: =Jan!$B$51 -> 0 | I16: =Jan!$B$51 -> 0 | J16: =Jan!$B$51 -> 0 | K16: =Jan!$B$51 -> 0 | L16: =Jan!$B$51 -> 0 | ... N16: =Jan!$B$51 -> 0 | O16: =SUM(C16:N16) -> 0
B17: Transporte | C17: =Jan!$B$59 -> 0 | D17: =Jan!$B$59 -> 0 | E17: =Jan!$B$59 -> 0 | F17: =Jan!$B$59 -> 0 | G17: =Jan!$B$59 -> 0 | H17: =Jan!$B$59 -> 0 | I17: =Jan!$B$59 -> 0 | J17: =Jan!$B$59 -> 0 | ... N17: =Jan!$B$59 -> 0 | O17: =SUM(C17:N17) -> 0
B18: Educação | C18: =Jan!$B$67 -> 0 | D18: =Jan!$B$67 -> 0 | E18: =Jan!$B$67 -> 0 | F18: =Jan!$B$67 -> 0 | G18: =Jan!$B$67 -> 0 | H18: =Jan!$B$67 -> 0 | I18: =Jan!$B$67 -> 0 | J18: =Jan!$B$67 -> 0 | ... N18: =Jan!$B$67 -> 0 | O18: =SUM(C18:N18) -> 0
B19: Saúde | C19: =Jan!$B$75 -> 0 | D19: =Jan!$B$75 -> 0 | E19: =Jan!$B$75 -> 0 | F19: =Jan!$B$75 -> 0 | G19: =Jan!$B$75 -> 0 | H19: =Jan!$B$75 -> 0 | I19: =Jan!$B$75 -> 0 | J19: =Jan!$B$75 -> 0 | ... N19: =Jan!$B$75 -> 0 | O19: =SUM(C19:N19) -> 0
B20: Imprevistos | C20: =Jan!$B$83 -> 0 | D20: =Jan!$B$83 -> 0 | E20: =Jan!$B$83 -> 0 | F20: =Jan!$B$83 -> 0 | G20: =Jan!$B$83 -> 0 | H20: =Jan!$B$83 -> 0 | I20: =Jan!$B$83 -> 0 | J20: =Jan!$B$83 -> 0 | ... N20: =Jan!$B$83 -> 0 | O20: =SUM(C20:N20) -> 0
B24: Alimentação | C24: Doces | D24: =SUBTOTAL(9,Fev!D35,Fev!D35,Mar!D35,Abr!D35,Mai!D35,Jun!D35,Jul!D35,Ago!D35,Set!D35,Out!D35,Nov!D35,Dez!D35) -> 14.98
B25: =SUM(D24:D28) -> 43.58 | C25: Padaria | D25: =SUBTOTAL(9,Fev!D36,Fev!D36,Mar!D36,Abr!D36,Mai!D36,Jun!D36,Jul!D36,Ago!D36,Set!D36,Out!D36,Nov!D36,Dez!D36) -> 0 | F25: Internet | G25: =SUBTOTAL(9,Jan!I35,Fev!I35,Mar!I35,Abr!I35,Mai!I35,Jun!I35,Jul!I35,Ago!I35,Set!I35,Out!I35,Nov!I35,Dez!I35) -> 30
C26: Almoço fora | D26: =SUBTOTAL(9,Fev!D37,Fev!D37,Mar!D37,Abr!D37,Mai!D37,Jun!D37,Jul!D37,Ago!D37,Set!D37,Out!D37,Nov!D37,Dez!D37) -> 0 | F26: Planos/assinaturas | G26: =SUBTOTAL(9,Jan!I36,Fev!I36,Mar!I36,Abr!I36,Mai!I36,Jun!I36,Jul!I36,Ago!I36,Set!I36,Out!I36,Nov!I36,Dez!I36) -> 13.6
C27: Lanches / Snacks | D27: =SUBTOTAL(9,Fev!D38,Fev!D38,Mar!D38,Abr!D38,Mai!D38,Jun!D38,Jul!D38,Ago!D38,Set!D38,Out!D38,Nov!D38,Dez!D38) -> 28.6 | F27: Agua | G27: =SUBTOTAL(9,Jan!I37,Fev!I37,Mar!I37,Abr!I37,Mai!I37,Jun!I37,Jul!I37,Ago!I37,Set!I37,Out!I37,Nov!I37,Dez!I37) -> 0
D28: =SUBTOTAL(9,Fev!D39,Fev!D39,Mar!D39,Abr!D39,Mai!D39,Jun!D39,Jul!D39,Ago!D39,Set!D39,Out!D39,Nov!D39,Dez!D39) -> 0 | F28: Luz | G28: =SUBTOTAL(9,Jan!I38,Fev!I38,Mar!I38,Abr!I38,Mai!I38,Jun!I38,Jul!I38,Ago!I38,Set!I38,Out!I38,Nov!I38,Dez!I38) -> 0
F29: Gasolina | G29: =SUBTOTAL(9,Jan!I39,Fev!I39,Mar!I39,Abr!I39,Mai!I39,Jun!I39,Jul!I39,Ago!I39,Set!I39,Out!I39,Nov!I39,Dez!I39) -> 30
B30: Lazer | C30: Delivery (iFood, etc) | D30: =SUBTOTAL(9,Fev!D41,Fev!D41,Mar!D41,Abr!D41,Mai!D41,Jun!D41,Jul!D41,Ago!D41,Set!D41,Out!D41,Nov!D41,Dez!D41) -> 0 | F30: Dizimos | G30: =SUBTOTAL(9,Jan!I40,Fev!I40,Mar!I40,Abr!I40,Mai!I40,Jun!I40,Jul!I40,Ago!I40,Set!I40,Out!I40,Nov!I40,Dez!I40) -> 0
B31: =SUM(D30:D37) -> 148.14 | C31: Cinema / Shows | D31: =SUBTOTAL(9,Fev!D42,Fev!D42,Mar!D42,Abr!D42,Mai!D42,Jun!D42,Jul!D42,Ago!D42,Set!D42,Out!D42,Nov!D42,Dez!D42) -> 57 | F31: Ofertas | G31: =SUBTOTAL(9,Jan!I41,Fev!I41,Mar!I41,Abr!I41,Mai!I41,Jun!I41,Jul!I41,Ago!I41,Set!I41,Out!I41,Nov!I41,Dez!I41) -> 0
C32: Passeios / Viagens | D32: =SUBTOTAL(9,Fev!D43,Fev!D43,Mar!D43,Abr!D43,Mai!D43,Jun!D43,Jul!D43,Ago!D43,Set!D43,Out!D43,Nov!D43,Dez!D43) -> 75 | F32: Parcelas | G32: =SUBTOTAL(9,Jan!I42,Fev!I42,Mar!I42,Abr!I42,Mai!I42,Jun!I42,Jul!I42,Ago!I42,Set!I42,Out!I42,Nov!I42,Dez!I42) -> 624.5
C33: Compras por impulso (não essenciais) | D33: =SUBTOTAL(9,Fev!D44,Fev!D44,Mar!D44,Abr!D44,Mai!D44,Jun!D44,Jul!D44,Ago!D44,Set!D44,Out!D44,Nov!D44,Dez!D44) -> 0 | F33: Saúde | G33: =SUBTOTAL(9,Jan!I43,Fev!I43,Mar!I43,Abr!I43,Mai!I43,Jun!I43,Jul!I43,Ago!I43,Set!I43,Out!I43,Nov!I43,Dez!I43) -> 0
C34: Jogos / Games / Aplicativos pagos | D34: =SUBTOTAL(9,Fev!D45,Fev!D45,Mar!D45,Abr!D45,Mai!D45,Jun!D45,Jul!D45,Ago!D45,Set!D45,Out!D45,Nov!D45,Dez!D45) -> 0 | F34: Investimento | G34: =SUBTOTAL(9,Jan!I44,Fev!I44,Mar!I44,Abr!I44,Mai!I44,Jun!I44,Jul!I44,Ago!I44,Set!I44,Out!I44,Nov!I44,Dez!I44) -> 0
C35: Saídas com amigos | D35: =SUBTOTAL(9,Fev!D46,Fev!D46,Mar!D46,Abr!D46,Mai!D46,Jun!D46,Jul!D46,Ago!D46,Set!D46,Out!D46,Nov!D46,Dez!D46) -> 16.14 | G35: =SUBTOTAL(9,Jan!I45,Fev!I45,Mar!I45,Abr!I45,Mai!I45,Jun!I45,Jul!I45,Ago!I45,Set!I45,Out!I45,Nov!I45,Dez!I45) -> 0
D36: =SUBTOTAL(9,Fev!D47,Fev!D47,Mar!D47,Abr!D47,Mai!D47,Jun!D47,Jul!D47,Ago!D47,Set!D47,Out!D47,Nov!D47,Dez!D47) -> 0
D37: =SUBTOTAL(9,Fev!D48,Fev!D48,Mar!D48,Abr!D48,Mai!D48,Jun!D48,Jul!D48,Ago!D48,Set!D48,Out!D48,Nov!D48,Dez!D48) -> 0
B39: Despesas | C39: Presentes e datas comemorativas | D39: =SUBTOTAL(9,Fev!D50,Fev!D50,Mar!D50,Abr!D50,Mai!D50,Jun!D50,Jul!D50,Ago!D50,Set!D50,Out!D50,Nov!D50,Dez!D50) -> 86
B40: =SUM(D39:D45) -> 372.57 | C40: Doações / Contribuições | D40: =SUBTOTAL(9,Fev!D51,Fev!D51,Mar!D51,Abr!D51,Mai!D51,Jun!D51,Jul!D51,Ago!D51,Set!D51,Out!D51,Nov!D51,Dez!D51) -> 0
C41: Taxas bancárias / Pix por engano | D41: =SUBTOTAL(9,Fev!D52,Fev!D52,Mar!D52,Abr!D52,Mai!D52,Jun!D52,Jul!D52,Ago!D52,Set!D52,Out!D52,Nov!D52,Dez!D52) -> 0
C42: Compras online aleatórias | D42: =SUBTOTAL(9,Fev!D53,Fev!D53,Mar!D53,Abr!D53,Mai!D53,Jun!D53,Jul!D53,Ago!D53,Set!D53,Out!D53,Nov!D53,Dez!D53) -> 200.27
C43: Manutenção da casa (lâmpada, pilha, etc) | D43: =SUBTOTAL(9,Fev!D54,Fev!D54,Mar!D54,Abr!D54,Mai!D54,Jun!D54,Jul!D54,Ago!D54,Set!D54,Out!D54,Nov!D54,Dez!D54) -> 22.5
C44: Gastos pessoais (roupas, acessórios) | D44: =SUBTOTAL(9,Fev!D55,Fev!D55,Mar!D55,Abr!D55,Mai!D55,Jun!D55,Jul!D55,Ago!D55,Set!D55,Out!D55,Nov!D55,Dez!D55) -> 63.8
D45: =SUBTOTAL(9,Fev!D56,Fev!D56,Mar!D56,Abr!D56,Mai!D56,Jun!D56,Jul!D56,Ago!D56,Set!D56,Out!D56,Nov!D56,Dez!D56) -> 0
B47: Transporte | C47: Acessório | D47: =SUBTOTAL(9,Fev!D58,Fev!D58,Mar!D58,Abr!D58,Mai!D58,Jun!D58,Jul!D58,Ago!D58,Set!D58,Out!D58,Nov!D58,Dez!D58) -> 0
B48: =SUM(D47:D53) -> 514.51 | C48: Uber / Táxi | D48: =SUBTOTAL(9,Fev!D59,Fev!D59,Mar!D59,Abr!D59,Mai!D59,Jun!D59,Jul!D59,Ago!D59,Set!D59,Out!D59,Nov!D59,Dez!D59) -> 54.51
C49: Ônibus / Metrô | D49: =SUBTOTAL(9,Fev!D60,Fev!D60,Mar!D60,Abr!D60,Mai!D60,Jun!D60,Jul!D60,Ago!D60,Set!D60,Out!D60,Nov!D60,Dez!D60) -> 0
C50: Estacionamento | D50: =SUBTOTAL(9,Fev!D61,Fev!D61,Mar!D61,Abr!D61,Mai!D61,Jun!D61,Jul!D61,Ago!D61,Set!D61,Out!D61,Nov!D61,Dez!D61) -> 0
...

Sheet Modelo
B2: MÊS | C2: entradas | D2: valor | F2: Saldo mensal
B3: salário | F3: =SUM(D3:D7) -> 0 | M3: Topicos | N3: Sub-tópicos | P3: Alimentação | R3: Internet
B4: Fotografia | F4: =SUM(F11:F32) -> 0 | M4: =P3 -> Alimentação | N4: Doces | P4: Lazer | R4: Planos/assinaturas
B5: extra 2 | F5: =D4 -> 0 | N5: Padaria | P5: Despesas | R5: Agua
F6: =SUM(K11:K22) -> 0 | N6: Almoço fora | P6: Moradia | R6: Luz
B7: saldo | D7: saldo do mês anterior | F7: =F3-F4-F6 -> 0 | N7: Lanches / Snacks | P7: Transporte | R7: Gasolina
P8: Educação | R8: Dizimos
B9: Variados | H9: Fixos | P9: Saúde | R9: Ofertas
B10: data | C10: topico | D10: sub-tópico | E10: descrição | F10: valor | H10: data | I10: Topico | J10: sub-tópico | K10: valor | M10: =P4 -> Lazer | N10: Delivery (iFood, etc) | P10: Imprevistos | R10: Parcelas
N11: Cinema / Shows | R11: Saúde
N12: Passeios / Viagens | R12: Investimento
N13: Jogos / Games / Aplicativos pagos
N14: Saídas com amigos
N15: Compras por impulso (não essenciais)
M19: =P5 -> Despesas | N19: Presentes e datas comemorativas
N20: Doações / Contribuições
N21: Taxas bancárias / Pix por engano
N22: Compras online aleatórias
N23: Manutenção da casa (lâmpada, pilha, etc)
N24: Gastos pessoais (roupas, acessórios)
M29: =P7 -> Transporte | N29: Acessórios
N30: Uber / Táxi
N31: Ônibus / Metrô
N32: Estacionamento
N33: Manutenção (óleo, pneu, etc)
N34: Multas / Documentação
B35: Alimentação | C35: Doces | D35: =SUMIF($D$11:$D$32,C35,$F$11:$F$32) -> 0
B36: =SUBTOTAL(9,D35:D39) -> 0 | C36: Padaria | D36: =SUMIF($D$11:$D$32,C36,$F$11:$F$32) -> 0 | H36: Eventos | I36: Data | J36: Descrição | K36: Entradas
C37: Almoço fora | D37: =SUMIF($D$11:$D$32,C37,$F$11:$F$32) -> 0 | M37: =P8 -> Educação | N37: Mensalidade de curso / escola
C38: Lanches / Snacks | D38: =SUMIF($D$11:$D$32,C38,$F$11:$F$32) -> 0 | N38: Cursos online (Udemy, Alura, etc)
D39: =SUMIF($D$11:$D$32,C39,$F$11:$F$32) -> 0 | N39: Material escolar / didático
N40: Livros e apostilas
B41: Lazer | C41: Delivery (iFood, etc) | D41: =SUMIF($D$11:$D$32,C41,$F$11:$F$32) -> 0 | N41: Internet dedicada para estudos
B42: =SUBTOTAL(9,D41:D48) -> 0 | C42: Cinema / Shows | D42: =SUMIF($D$11:$D$32,C42,$F$11:$F$32) -> 0 | N42: Plataformas de aprendizado
C43: Passeios / Viagens | D43: =SUMIF($D$11:$D$32,C43,$F$11:$F$32) -> 0
C44: Compras por impulso (não essenciais) | D44: =SUMIF($D$11:$D$32,C44,$F$11:$F$32) -> 0
C45: Jogos / Games / Aplicativos pagos | D45: =SUMIF($D$11:$D$32,C45,$F$11:$F$32) -> 0 | M45: =P9 -> Saúde | N45: Medicamentos
C46: Saídas com amigos | D46: =SUMIF($D$11:$D$32,C46,$F$11:$F$32) -> 0 | N46: Consultas médicas / exames
D47: =SUMIF($D$11:$D$32,C47,$F$11:$F$32) -> 0 | N47: Plano de saúde
D48: =SUMIF($D$11:$D$32,C48,$F$11:$F$32) -> 0 | N48: Óculos / lentes
...
