Workbook

Sheet Jan
B2: JAN | C2: entradas | D2: valor | F2: Saldo mensal
B3: salário | C3: entrada total - tudo que tenho | D3: 1443.24 | E3: entradas | F3: =SUM(D3,D5,D6,D7,D4) -> 2246.57 | I3: data | K3: dinheiro guardado
B4: Fotografia | D4: =SUM(P10:P25) -> 103.33 | E4: gastos variados | F4: =SUM(F11:F32) -> 568.02 | I4: =TODAY() -> 46242 | K4: dinheiro para inestimento futuro
B5: extra 2 | D5: 700 | E5: entradas fotografia | F5: =D4 -> 103.33 | I5: ultimo update | K5: dinheiro para lente | L5: =SUM(P10:P25) -> 103.33
B6: extra 3 | E6: saidas fixas | F6: =SUM(K11:K22) -> 337 | I6: 46026 | K6: para passar o mês, tenho =>
E7: saldo | F7: =F3-F4-F6 -> 1341.55
B9: Variados | H9: Fixos | M9: Trabalho | N9: Data | O9: Descrição | P9: Entradas
B10: data | C10: topico | D10: sub-tópico | E10: descrição | F10: valor | H10: data | I10: Topico | J10: sub-tópico | K10: valor | M10: Astra | N10: 46044 | O10: fotos de carro, Astra | P10: 50
B11: 46026 | C11: Despesas | D11: Compras online aleatórias | E11: presente da marcelles | F11: 63 | H11: 46026 | I11: Planos/assinaturas | J11: internet 5G | K11: 30 | M11: fotos do volei + banlek acumulado | N11: 46048 | O11: fotos do volei | P11: 53.33
B12: 46028 | C12: Transporte | D12: Uber / Táxi | E12: gasolina pro coroa | F12: 30 | H12: 46027 | I12: Parcelas | J12: camera | K12: 147
B13: 46029 | C13: Despesas | D13: Fotografia (equipamentos e cursos) | E13: flash | F13: 349 | H13: 46034 | I13: Planos/assinaturas | J13: volei | K13: 30
B14: 46029 | C14: Transporte | D14: Manutenção (óleo, pneu, etc) | E14: oléo | F14: 42 | H14: 46032 | I14: Gasolina | K14: 30
B15: 46031 | C15: Lazer | D15: Saídas com amigos | E15: açaí | F15: 23.69 | H15: 46035 | I15: Parcelas | J15: acampamento | K15: 70
B16: 46036 | C16: lazer | D16: Esportes / saidas | E16: volei | F16: 24 | H16: 46038 | I16: Planos/assinaturas | J16: babeiro | K16: 30
B17: 46040 | C17: Despesas | D17: Doações / Contribuições | E17: oferta | F17: 10
B18: 46045 | C18: Despesas | D18: Gastos pessoais (roupas, acessórios) | E18: padaria e armazem (trena) | F18: 20.95
B19: 46047 | C19: alimentação | D19: Supermercado | E19: supermecado brasil | F19: 5.38
B21: 46141
K23: =SUM(K11:K22) -> 337
B35: Alimentação | C35: Doces | D35: =SUMIF($D$11:$D$32,C35,$F$11:$F$32) -> 0 | H35: Internet | I35: =SUMIF($I$11:$I$22,H35,$K$11:$K$22) -> 0
B36: =SUM(D35:D39) -> 0 | C36: Padaria | D36: =SUMIF($D$11:$D$32,C36,$F$11:$F$32) -> 0 | H36: Planos/assinaturas | I36: =SUMIF($I$11:$I$22,H36,$K$11:$K$22) -> 90
C37: Almoço fora | D37: =SUMIF($D$11:$D$32,C37,$F$11:$F$32) -> 0 | H37: Agua | I37: =SUMIF($I$11:$I$22,H37,$K$11:$K$22) -> 0
C38: Lanches / Snacks | D38: =SUMIF($D$11:$D$32,C38,$F$11:$F$32) -> 0 | H38: Luz | I38: =SUMIF($I$11:$I$22,H38,$K$11:$K$22) -> 0
D39: =SUMIF($D$11:$D$32,C39,$F$11:$F$32) -> 0 | H39: Gasolina | I39: =SUMIF($I$11:$I$22,H39,$K$11:$K$22) -> 30
H40: Dizimos | I40: =SUMIF($I$11:$I$22,H40,$K$11:$K$22) -> 0
B41: Lazer | C41: Delivery (iFood, etc) | D41: =SUMIF($D$11:$D$32,C41,$F$11:$F$32) -> 0 | H41: Ofertas | I41: =SUMIF($I$11:$I$22,H41,$K$11:$K$22) -> 0
B42: =SUBTOTAL(9,D41:D48) -> 23.69 | C42: Cinema / Shows | D42: =SUMIF($D$11:$D$32,C42,$F$11:$F$32) -> 0 | H42: Parcelas | I42: =SUMIF($I$11:$I$22,H42,$K$11:$K$22) -> 217
C43: Passeios / Viagens | D43: =SUMIF($D$11:$D$32,C43,$F$11:$F$32) -> 0 | H43: Saúde | I43: =SUMIF($I$11:$I$22,H43,$K$11:$K$22) -> 0
C44: Compras por impulso (não essenciais) | D44: =SUMIF($D$11:$D$32,C44,$F$11:$F$32) -> 0 | H44: Investimento | I44: =SUMIF($I$11:$I$22,H44,$K$11:$K$22) -> 0
C45: Jogos / Games / Aplicativos pagos | D45: =SUMIF($D$11:$D$32,C45,$F$11:$F$32) -> 0 | I45: =SUMIF($I$11:$I$22,H45,$K$11:$K$22) -> 0
C46: Saídas com amigos | D46: =SUMIF($D$11:$D$32,C46,$F$11:$F$32) -> 23.69
D47: =SUMIF($D$11:$D$32,C47,$F$11:$F$32) -> 0
D48: =SUMIF($D$11:$D$32,C48,$F$11:$F$32) -> 0
B50: Despesas | C50: Presentes e datas comemorativas | D50: =SUMIF($D$11:$D$32,C50,$F$11:$F$32) -> 0
B51: =SUM(D50:D56) -> 93.95 | C51: Doações / Contribuições | D51: =SUMIF($D$11:$D$32,C51,$F$11:$F$32) -> 10
C52: Taxas bancárias / Pix por engano | D52: =SUMIF($D$11:$D$32,C52,$F$11:$F$32) -> 0
C53: Compras online aleatórias | D53: =SUMIF($D$11:$D$32,C53,$F$11:$F$32) -> 63
C54: Manutenção da casa (lâmpada, pilha, etc) | D54: =SUMIF($D$11:$D$32,C54,$F$11:$F$32) -> 0
C55: Gastos pessoais (roupas, acessórios) | D55: =SUMIF($D$11:$D$32,C55,$F$11:$F$32) -> 20.95
D56: =SUMIF($D$11:$D$32,C56,$F$11:$F$32) -> 0
...

Sheet Fev
B2: Fev | C2: entradas | D2: valor | F2: Saldo mensal
B3: salário | D3: 740 | E3: entradas | F3: =SUM(D3,D5,D6,D7,D4) -> 2281.55 | I3: data | K3: dinheiro guardado
B4: Fotografia | D4: =SUM(P10:P25) -> 200 | E4: gastos variados | F4: =SUM(F11:F32) -> 561.58 | I4: =TODAY() -> 46242 | K4: dinheiro para inestimento futuro
B5: extra 2 | E5: entradas fotografia | F5: =D4 -> 200 | I5: ultimo update | K5: dinheiro para lente | L5: =SUM(P10:P25) -> 200
B6: extra 3 | E6: saidas fixas | F6: =SUM(K11:K22) -> 362.2 | I6: 45847 | K6: para passar o mês, tenho =>
B7: Saldo | D7: =Jan!F7 -> 1341.55 | E7: saldo | F7: =F3-F4-F6 -> 1357.77
B9: Variados | H9: Fixos | M9: Eventos | N9: Data | O9: Descrição | P9: Entradas
B10: data | C10: topico | D10: sub-tópico | E10: descrição | F10: valor | H10: data | I10: Topico | J10: sub-tópico | K10: valor | M10: Bernardo | N10: 46081 | O10: aiversario do Be | P10: 200
B11: 46064 | C11: Despesas | D11: Gastos pessoais (roupas, acessórios) | E11: tenis | F11: =39+135 -> 174 | H11: 46054 | I11: Ofertas | J11: betel | K11: 40
B12: 46066 | C12: Transporte | D12: Multas / Documentação | E12: ipva | F12: 238.42 | H12: 46055 | I12: Gasolina | J12: mensal | K12: =25.1+31.6 -> 56.7
B13: 46066 | C13: Transporte | D13: Manutenção (óleo, pneu, etc) | E13: gasolina pra manu | F13: 57.92 | H13: 46062 | I13: Parcelas | J13: cannon | K13: 143.5
B14: 46068 | C14: Despesas | D14: Gastos pessoais (roupas, acessórios) | E14: brasil | F14: =37.14+15.1 -> 52.24 | H14: 46062 | I14: Parcelas | J14: sitio | K14: 70
B15: 46081 | C15: Lazer | D15: Saídas com amigos | E15: churrasco | F15: 39 | H15: 46063 | I15: Planos/assinaturas | J15: spotify | K15: 7
H16: 46064 | I16: Planos/assinaturas | J16: claro | K16: 30
H17: 46065 | I17: Planos/assinaturas | J17: volei | K17: 15
B21: 46141
K23: =SUM(K11:K22) -> 362.2
B35: Alimentação | C35: Doces | D35: =SUMIF($D$11:$D$32,C35,$F$11:$F$32) -> 0 | H35: Internet | I35: =SUMIF($I$11:$I$22,H35,$K$11:$K$22) -> 0
B36: =SUM(D35:D39) -> 0 | C36: Padaria | D36: =SUMIF($D$11:$D$32,C36,$F$11:$F$32) -> 0 | H36: Planos/assinaturas | I36: =SUMIF($I$11:$I$22,H36,$K$11:$K$22) -> 52
C37: Almoço fora | D37: =SUMIF($D$11:$D$32,C37,$F$11:$F$32) -> 0 | H37: Agua | I37: =SUMIF($I$11:$I$22,H37,$K$11:$K$22) -> 0
C38: Lanches / Snacks | D38: =SUMIF($D$11:$D$32,C38,$F$11:$F$32) -> 0 | H38: Luz | I38: =SUMIF($I$11:$I$22,H38,$K$11:$K$22) -> 0
D39: =SUMIF($D$11:$D$32,C39,$F$11:$F$32) -> 0 | H39: Gasolina | I39: =SUMIF($I$11:$I$22,H39,$K$11:$K$22) -> 56.7
H40: Dizimos | I40: =SUMIF($I$11:$I$22,H40,$K$11:$K$22) -> 0
B41: Lazer | C41: Delivery (iFood, etc) | D41: =SUMIF($D$11:$D$32,C41,$F$11:$F$32) -> 0 | H41: Ofertas | I41: =SUMIF($I$11:$I$22,H41,$K$11:$K$22) -> 40
B42: =SUBTOTAL(9,D41:D48) -> 39 | C42: Cinema / Shows | D42: =SUMIF($D$11:$D$32,C42,$F$11:$F$32) -> 0 | H42: Parcelas | I42: =SUMIF($I$11:$I$22,H42,$K$11:$K$22) -> 213.5
C43: Passeios / Viagens | D43: =SUMIF($D$11:$D$32,C43,$F$11:$F$32) -> 0 | H43: Saúde | I43: =SUMIF($I$11:$I$22,H43,$K$11:$K$22) -> 0
C44: Compras por impulso (não essenciais) | D44: =SUMIF($D$11:$D$32,C44,$F$11:$F$32) -> 0 | H44: Investimento | I44: =SUMIF($I$11:$I$22,H44,$K$11:$K$22) -> 0
C45: Jogos / Games / Aplicativos pagos | D45: =SUMIF($D$11:$D$32,C45,$F$11:$F$32) -> 0 | I45: =SUMIF($I$11:$I$22,H45,$K$11:$K$22) -> 0
C46: Saídas com amigos | D46: =SUMIF($D$11:$D$32,C46,$F$11:$F$32) -> 39
D47: =SUMIF($D$11:$D$32,C47,$F$11:$F$32) -> 0
D48: =SUMIF($D$11:$D$32,C48,$F$11:$F$32) -> 0
B50: Despesas | C50: Presentes e datas comemorativas | D50: =SUMIF($D$11:$D$32,C50,$F$11:$F$32) -> 0
B51: =SUM(D50:D56) -> 226.24 | C51: Doações / Contribuições | D51: =SUMIF($D$11:$D$32,C51,$F$11:$F$32) -> 0
C52: Taxas bancárias / Pix por engano | D52: =SUMIF($D$11:$D$32,C52,$F$11:$F$32) -> 0
C53: Compras online aleatórias | D53: =SUMIF($D$11:$D$32,C53,$F$11:$F$32) -> 0
C54: Manutenção da casa (lâmpada, pilha, etc) | D54: =SUMIF($D$11:$D$32,C54,$F$11:$F$32) -> 0
C55: Gastos pessoais (roupas, acessórios) | D55: =SUMIF($D$11:$D$32,C55,$F$11:$F$32) -> 226.24
D56: =SUMIF($D$11:$D$32,C56,$F$11:$F$32) -> 0
B58: Transporte | C58: Acessório | D58: =SUMIF($D$11:$D$32,C58,$F$11:$F$32) -> 0
B59: =SUM(D58:D64) -> 296.34 | C59: Uber / Táxi | D59: =SUMIF($D$11:$D$32,C59,$F$11:$F$32) -> 0
...

Sheet Mar
B2: MAR | C2: entradas | D2: valor | F2: Saldo mensal
B3: salário | D3: 500 | E3: entradas | F3: =SUM(D3,D5,D6,D7,D4) -> 2080.77 | I3: data | K3: dinheiro guardado
B4: Fotografia | D4: =SUM(P10:P25) -> 0 | E4: gastos variados | F4: =SUM(F11:F32) -> 1203.63 | I4: =TODAY() -> 46242 | K4: dinheiro para inestimento futuro
B5: extra 2 | D5: 223 | E5: entradas fotografia | F5: =D4 -> 0 | I5: ultimo update | K5: dinheiro para lente | L5: =SUM(P10:P25) -> 0
B6: extra 3 | E6: saidas fixas | F6: =SUM(K11:K22) -> 434.6 | I6: 45847 | K6: para passar o mês, tenho =>
B7: Saldo | D7: =Fev!F7 -> 1357.77 | E7: saldo | F7: =F3-(F4+F6) -> 442.54
B9: Variados | H9: Fixos | M9: Eventos | N9: Data | O9: Descrição | P9: Entradas
B10: data | C10: topico | D10: sub-tópico | E10: descrição | F10: valor | H10: data | I10: Topico | J10: sub-tópico | K10: valor
B11: 46083 | C11: Educação | D11: Material escolar / didático | E11: pasta, calculadora | F11: 34.45 | H11: 46084 | I11: Gasolina | K11: 55.8
B12: 46087 | C12: Transporte | D12: Manutenção (óleo, pneu, etc) | E12: relação | F12: 210 | H12: 46088 | I12: Planos/assinaturas | J12: spotify | K12: 6.8
B13: 46088 | C13: Lazer | D13: Delivery (iFood, etc) | E13: monster | F13: =8.44*2 -> 16.88 | H13: 46088 | I13: Internet | K13: 30
B14: 46088 | C14: Lazer | D14: Delivery (iFood, etc) | E14: churrasco | F14: 31 | H14: 46089 | I14: Dizimos | K14: 50
B15: 46092 | C15: Despesas | D15: Compras online aleatórias | E15: balaclava | F15: 19.3 | H15: 46099 | I15: Planos/assinaturas | J15: volei | K15: 40
B16: 46098 | C16: Imprevistos | D16: Conserto urgente (casa, carro, etc) | E16: moto | F16: 880 | H16: 46091 | I16: Parcelas | J16: cannon | K16: 149.5
B17: 46101 | C17: alimentação | D17: Padaria | E17: hamburgao | F17: 12 | H17: 46103 | I17: Planos/assinaturas | K17: 67.5
H18: 46101 | I18: Barbeiro | K18: 35
B21: 46141
K23: =SUM(K11:K22) -> 434.6
B35: Alimentação | C35: Doces | D35: =SUMIF($D$11:$D$32,C35,$F$11:$F$32) -> 0 | H35: Internet | I35: =SUMIF($I$11:$I$22,H35,$K$11:$K$22) -> 30
B36: =SUM(D35:D39) -> 12 | C36: Padaria | D36: =SUMIF($D$11:$D$32,C36,$F$11:$F$32) -> 12 | H36: Planos/assinaturas | I36: =SUMIF($I$11:$I$22,H36,$K$11:$K$22) -> 114.3
C37: Almoço fora | D37: =SUMIF($D$11:$D$32,C37,$F$11:$F$32) -> 0 | H37: Agua | I37: =SUMIF($I$11:$I$22,H37,$K$11:$K$22) -> 0
C38: Lanches / Snacks | D38: =SUMIF($D$11:$D$32,C38,$F$11:$F$32) -> 0 | H38: Luz | I38: =SUMIF($I$11:$I$22,H38,$K$11:$K$22) -> 0
D39: =SUMIF($D$11:$D$32,C39,$F$11:$F$32) -> 0 | H39: Gasolina | I39: =SUMIF($I$11:$I$22,H39,$K$11:$K$22) -> 55.8
H40: Dizimos | I40: =SUMIF($I$11:$I$22,H40,$K$11:$K$22) -> 50
B41: Lazer | C41: Delivery (iFood, etc) | D41: =SUMIF($D$11:$D$32,C41,$F$11:$F$32) -> 47.88 | H41: Ofertas | I41: =SUMIF($I$11:$I$22,H41,$K$11:$K$22) -> 0
B42: =SUBTOTAL(9,D41:D48) -> 47.88 | C42: Cinema / Shows | D42: =SUMIF($D$11:$D$32,C42,$F$11:$F$32) -> 0 | H42: Parcelas | I42: =SUMIF($I$11:$I$22,H42,$K$11:$K$22) -> 149.5
C43: Passeios / Viagens | D43: =SUMIF($D$11:$D$32,C43,$F$11:$F$32) -> 0 | H43: Saúde | I43: =SUMIF($I$11:$I$22,H43,$K$11:$K$22) -> 0
C44: Compras por impulso (não essenciais) | D44: =SUMIF($D$11:$D$32,C44,$F$11:$F$32) -> 0 | H44: Investimento | I44: =SUMIF($I$11:$I$22,H44,$K$11:$K$22) -> 0
C45: Jogos / Games / Aplicativos pagos | D45: =SUMIF($D$11:$D$32,C45,$F$11:$F$32) -> 0 | I45: =SUMIF($I$11:$I$22,H45,$K$11:$K$22) -> 0
C46: Saídas com amigos | D46: =SUMIF($D$11:$D$32,C46,$F$11:$F$32) -> 0
D47: =SUMIF($D$11:$D$32,C47,$F$11:$F$32) -> 0
D48: =SUMIF($D$11:$D$32,C48,$F$11:$F$32) -> 0
B50: Despesas | C50: Presentes e datas comemorativas | D50: =SUMIF($D$11:$D$32,C50,$F$11:$F$32) -> 0
B51: =SUM(D50:D56) -> 19.3 | C51: Doações / Contribuições | D51: =SUMIF($D$11:$D$32,C51,$F$11:$F$32) -> 0
C52: Taxas bancárias / Pix por engano | D52: =SUMIF($D$11:$D$32,C52,$F$11:$F$32) -> 0
C53: Compras online aleatórias | D53: =SUMIF($D$11:$D$32,C53,$F$11:$F$32) -> 19.3
C54: Manutenção da casa (lâmpada, pilha, etc) | D54: =SUMIF($D$11:$D$32,C54,$F$11:$F$32) -> 0
C55: Gastos pessoais (roupas, acessórios) | D55: =SUMIF($D$11:$D$32,C55,$F$11:$F$32) -> 0
D56: =SUMIF($D$11:$D$32,C56,$F$11:$F$32) -> 0
B58: Transporte | C58: Acessório | D58: =SUMIF($D$11:$D$32,C58,$F$11:$F$32) -> 0
...

Sheet Abr
B2: ABR | C2: entradas | D2: valor | F2: Saldo mensal
B3: salário | D3: 2100 | E3: entradas | F3: =SUM(D3,D5,D6,D7,D4) -> 2679.04 | I3: data | K3: dinheiro guardado | L3: 1343
B4: Fotografia | D4: =SUM(P10:P25) -> 136.5 | E4: gastos variados | F4: =SUM(F11:F32) -> 723.11 | I4: =TODAY() -> 46242 | K4: dinheiro para inestimento futuro | L4: =1185.57-201.64 -> 983.93
B5: extra 2 | E5: entradas fotografia | F5: =D4 -> 136.5 | I5: ultimo update | K5: dinheiro para lente | L5: =SUM(P10:P25) -> 136.5
B6: extra 3 | E6: saidas fixas | F6: =SUM(K11:K22) -> 516.69 | I6: 46136 | K6: para passar o mês, tenho => | L6: =274.72-67.7-23.36-48-48.5-8.6-35.31-37.5-50-6.69 -> -50.94
B7: Saldo | D7: =Mar!F7 -> 442.54 | E7: saldo | F7: =F3-F4-F6 -> 1439.24 | K7: qualeasenha?
B9: Variados | H9: Fixos | M9: Eventos | N9: Data | O9: Descrição | P9: Entradas
B10: data | C10: topico | D10: sub-tópico | E10: descrição | F10: valor | H10: data | I10: Topico | J10: sub-tópico | K10: valor | M10: peguei dinheiro na banlek | N10: 46136 | O10: dinheiro | P10: 136.5
B11: 46118 | C11: Alimentação | D11: Padaria | E11: lanche pra facul | F11: 17.5 | H11: 46114 | I11: Gasolina | K11: =78+6.69 -> 84.69
B12: 46119 | C12: Alimentação | D12: Padaria | E12: lanche pra igreja eu acho | F12: 30 | H12: 46114 | I12: Planos/assinaturas | J12: net | K12: 30
B13: 46123 | C13: Lazer | D13: Cinema / Shows | E13: show projeto sola, ingresso | F13: 155 | H13: 46114 | I13: Planos/assinaturas | J13: spotify | K13: 7
B14: 46124 | C14: Despesas | D14: Compras online aleatórias | E14: jo e livro | F14: =3.78+1.78+62.14 -> 67.7 | H14: 46123 | I14: Dizimos | J14: dizimo do mês | K14: 210
B15: 46124 | C15: Alimentação | D15: Doces | E15: acai | F15: 23.36 | H15: 46123 | I15: Parcelas | J15: camera | K15: 150
B16: 46132 | C16: Despesas | D16: Compras online aleatórias | E16: camisa campeonato | F16: 48 | H16: 46130 | I16: Barbeiro | K16: 35
B17: 46133 | C17: Transporte | D17: Manutenção (óleo, pneu, etc) | E17: gasolina pra são joao | F17: 48.5
B18: 46134 | C18: Alimentação | D18: Padaria | F18: 8.6
B19: 46138 | C19: Lazer | D19: Saídas com amigos | E19: manu | F19: 35.31
B20: 46139 | C20: Despesas | D20: Presentes e datas comemorativas | E20: lorena e jão | F20: 37.5
B21: 46141 | C21: Investimento | E21: pc - gabinete | F21: 201.64
B22: 46142 | C22: Imprevistos | D22: Equipamento quebrado (celular, notebook) | E22: moto bati | F22: 50
K23: =SUM(K11:K22) -> 516.69
B35: Alimentação | C35: Doces | D35: =SUMIF($D$11:$D$32,C35,$F$11:$F$32) -> 23.36 | H35: Internet | I35: =SUMIF($I$11:$I$22,H35,$K$11:$K$22) -> 0
B36: =SUM(D35:D39) -> 79.46 | C36: Padaria | D36: =SUMIF($D$11:$D$32,C36,$F$11:$F$32) -> 56.1 | H36: Planos/assinaturas | I36: =SUMIF($I$11:$I$22,H36,$K$11:$K$22) -> 37
C37: Almoço fora | D37: =SUMIF($D$11:$D$32,C37,$F$11:$F$32) -> 0 | H37: Agua | I37: =SUMIF($I$11:$I$22,H37,$K$11:$K$22) -> 0
C38: Lanches / Snacks | D38: =SUMIF($D$11:$D$32,C38,$F$11:$F$32) -> 0 | H38: Luz | I38: =SUMIF($I$11:$I$22,H38,$K$11:$K$22) -> 0
D39: =SUMIF($D$11:$D$32,C39,$F$11:$F$32) -> 0 | H39: Gasolina | I39: =SUMIF($I$11:$I$22,H39,$K$11:$K$22) -> 84.69
H40: Dizimos | I40: =SUMIF($I$11:$I$22,H40,$K$11:$K$22) -> 210
B41: Lazer | C41: Delivery (iFood, etc) | D41: =SUMIF($D$11:$D$32,C41,$F$11:$F$32) -> 0 | H41: Ofertas | I41: =SUMIF($I$11:$I$22,H41,$K$11:$K$22) -> 0
B42: =SUBTOTAL(9,D41:D48) -> 190.31 | C42: Cinema / Shows | D42: =SUMIF($D$11:$D$32,C42,$F$11:$F$32) -> 155 | H42: Parcelas | I42: =SUMIF($I$11:$I$22,H42,$K$11:$K$22) -> 150
C43: Passeios / Viagens | D43: =SUMIF($D$11:$D$32,C43,$F$11:$F$32) -> 0 | H43: Saúde | I43: =SUMIF($I$11:$I$22,H43,$K$11:$K$22) -> 0
C44: Compras por impulso (não essenciais) | D44: =SUMIF($D$11:$D$32,C44,$F$11:$F$32) -> 0 | H44: Investimento | I44: =SUMIF($I$11:$I$22,H44,$K$11:$K$22) -> 0
C45: Jogos / Games / Aplicativos pagos | D45: =SUMIF($D$11:$D$32,C45,$F$11:$F$32) -> 0 | I45: =SUMIF($I$11:$I$22,H45,$K$11:$K$22) -> 0
C46: Saídas com amigos | D46: =SUMIF($D$11:$D$32,C46,$F$11:$F$32) -> 35.31
D47: =SUMIF($D$11:$D$32,C47,$F$11:$F$32) -> 0
D48: =SUMIF($D$11:$D$32,C48,$F$11:$F$32) -> 0
B50: Despesas | C50: Presentes e datas comemorativas | D50: =SUMIF($D$11:$D$32,C50,$F$11:$F$32) -> 37.5
B51: =SUM(D50:D56) -> 153.2 | C51: Doações / Contribuições | D51: =SUMIF($D$11:$D$32,C51,$F$11:$F$32) -> 0
C52: Taxas bancárias / Pix por engano | D52: =SUMIF($D$11:$D$32,C52,$F$11:$F$32) -> 0
C53: Compras online aleatórias | D53: =SUMIF($D$11:$D$32,C53,$F$11:$F$32) -> 115.7
C54: Manutenção da casa (lâmpada, pilha, etc) | D54: =SUMIF($D$11:$D$32,C54,$F$11:$F$32) -> 0
...

Sheet Mai
B2: MAI | C2: entradas | D2: valor | F2: Saldo mensal | N2: tenho | O2: retirei esse mês
B3: salário | D3: =2500-O3-50 -> 146 | E3: entradas | F3: =SUM(D3,D5,D6,D7,D4,L3,N3,L5) -> 4523.74 | I3: data | K3: dinheiro guardado | L3: =(Abr!L3+320+840) -> 2503 | N3: =L3-O3 -> 199 | O3: =300+500+150+400+50+630+10+210+54 -> 2304
B4: Fotografia | D4: =SUM(P10:P25) -> 20 | E4: gastos variados | F4: =SUM(F11:F26) -> 3935.01 | I4: =TODAY() -> 46242 | K4: dinheiro para investimento futuro | L4: 0
B5: extra 2 | D5: 60 | E5: entradas fotografia | F5: =D4 -> 20 | I5: ultimo update | K5: dinheiro para lente | L5: =Abr!L5+SUM(P10:P25) -> 156.5
B6: extra 3 | E6: saidas fixas | F6: =SUM(K11:K22) -> 597.03 | I6: 46173 | K6: para passar o mês, tenho => | M6: estou me devendo =>
B7: Saldo | D7: =Abr!F7 -> 1439.24 | E7: saldo | F7: =F3-F4-F6 -> -8.3
B9: Variados | H9: Fixos | M9: Eventos | N9: Data | O9: Descrição | P9: Entradas
B10: data | C10: topico | D10: sub-tópico | E10: descrição | F10: valor | H10: data | I10: Topico | J10: sub-tópico | K10: valor | M10: edição | N10: 46144 | O10: maycon | P10: 20
B11: 46144 | C11: Lazer | D11: Esportes / saidas | E11: volei | F11: =10+1.69 -> 11.69 | H11: 46144 | I11: Gasolina | K11: =75.03+13.18+30+13.22 -> 131.43
B12: 46145 | C12: Alimentação | D12: Almoço fora | E12: churrasco e sucos | F12: 28 | H12: 46145 | I12: Planos/assinaturas | J12: spotify | K12: =6.8+6.8 -> 13.6
B13: 46145 | C13: Investimento | E13: pc - placa mãe | F13: 1289.99 | H13: 46147 | I13: Planos/assinaturas | K13: 30
B14: 46144 | C14: Lazer | D14: Saídas com amigos | E14: joyce | F14: 44.7 | H14: 46150 | I14: Dizimos | K14: =2400*0.1 -> 240
B15: 46147 | C15: Transporte | D15: Manutenção (óleo, pneu, etc) | E15: oleo | F15: 48 | H15: 46153 | I15: Parcelas | J15: cannon | K15: 147
B16: 46151 | C16: Despesas | D16: Presentes e datas comemorativas | E16: mae | F16: 69.9 | H16: 46161 | I16: Barbeiro | K16: 35
B17: 46151 | C17: Investimento | E17: pc - processador | F17: 350
B18: 46125 | C18: Investimento | E18: pc - fonte e cooler | F18: 448.74
B19: 46157 | C19: Investimento | E19: pc - mouse e mouse pad | F19: 281.76
B20: 46163 | C20: Despesas | D20: Compras online aleatórias | E20: facul | F20: 7
B21: 46163 | C21: Alimentação | D21: Almoço fora | F21: 85
B22: 46163 | C22: Investimento | E22: pc - teclado | F22: 394.14
B23: 46164 | C23: Investimento | E23: pc - monitor | F23: 629
C24: Alimentação | D24: Supermercado | F24: =4.58+9 -> 13.58
C25: Investimento | E25: pc - ventuinhas | F25: 208.51
C26: Lazer | D26: Saídas com amigos | F26: 25
C27: Investimento | E27: pc - ram | F27: 1738.04
C28: Investimento | E28: Pc – ventoinhas | F28: 208.51
B35: Alimentação | C35: Doces | D35: =SUMIF($D$11:$D$32,C35,$F$11:$F$32) -> 0 | H35: Internet | I35: =SUMIF($I$11:$I$22,H35,$K$11:$K$22) -> 0
B36: =SUM(D35:D39) -> 0 | C36: Padaria | D36: =SUMIF($D$11:$D$32,C36,$F$11:$F$32) -> 0 | H36: Planos/assinaturas | I36: =SUMIF($I$11:$I$22,H36,$K$11:$K$22) -> 43.6
C37: Almoço fora | D37: =SUMIF($D$11:$D$32,C37,$F$11:$F$32) -> 0 | H37: Agua | I37: =SUMIF($I$11:$I$22,H37,$K$11:$K$22) -> 0
C38: Lanches / Snacks | D38: =SUMIF($D$11:$D$32,C38,$F$11:$F$32) -> 0 | H38: Luz | I38: =SUMIF($I$11:$I$22,H38,$K$11:$K$22) -> 0
D39: =SUMIF($D$11:$D$32,C39,$F$11:$F$32) -> 0 | H39: Gasolina | I39: =SUMIF($I$11:$I$22,H39,$K$11:$K$22) -> 131.43
H40: Dizimos | I40: =SUMIF($I$11:$I$22,H40,$K$11:$K$22) -> 240
B41: Lazer | C41: Delivery (iFood, etc) | D41: =SUMIF($D$11:$D$32,C41,$F$11:$F$32) -> 0 | H41: Ofertas | I41: =SUMIF($I$11:$I$22,H41,$K$11:$K$22) -> 0
B42: =SUBTOTAL(9,D41:D48) -> 69.7 | C42: Cinema / Shows | D42: =SUMIF($D$11:$D$32,C42,$F$11:$F$32) -> 0 | H42: Parcelas | I42: =SUMIF($I$11:$I$22,H42,$K$11:$K$22) -> 147
C43: Passeios / Viagens | D43: =SUMIF($D$11:$D$32,C43,$F$11:$F$32) -> 0 | H43: Saúde | I43: =SUMIF($I$11:$I$22,H43,$K$11:$K$22) -> 0
C44: Compras por impulso (não essenciais) | D44: =SUMIF($D$11:$D$32,C44,$F$11:$F$32) -> 0 | H44: Investimento | I44: =SUMIF($I$11:$I$22,H44,$K$11:$K$22) -> 0
C45: Jogos / Games / Aplicativos pagos | D45: =SUMIF($D$11:$D$32,C45,$F$11:$F$32) -> 0 | I45: =SUMIF($I$11:$I$22,H45,$K$11:$K$22) -> 0
C46: Saídas com amigos | D46: =SUMIF($D$11:$D$32,C46,$F$11:$F$32) -> 69.7
D47: =SUMIF($D$11:$D$32,C47,$F$11:$F$32) -> 0
D48: =SUMIF($D$11:$D$32,C48,$F$11:$F$32) -> 0
...

Sheet Jun
B2: JUN | C2: entradas | D2: valor | F2: Saldo mensal
B3: salário | D3: 2318 | E3: entradas | F3: =SUM(D3,D5,D6,D7,D4) -> 2309.7 | I3: data | K3: dinheiro guardado | L3: 200
B4: Fotografia | D4: =SUM(P10:P25) -> 0 | E4: gastos variados | F4: =SUM(F11:F32) -> 630 | I4: =TODAY() -> 46242 | K4: dinheiro para inVestimento futuro | L4: =Mai!L4 -> 0
B5: extra 2 | E5: entradas fotografia | F5: =D4 -> 0 | I5: ultimo update | K5: dinheiro para lente | L5: =Mai!L5 -> 156.5
B6: extra 3 | E6: saidas fixas | F6: =SUM(K11:K22) -> 1391.7 | I6: 46201 | K6: para passar o mês, tenho =>
B7: Saldo | D7: =Mai!F7 -> -8.3 | E7: saldo | F7: =F3-F4-F6 -> 288
B9: Variados | H9: Fixos | M9: Eventos | N9: Data | O9: Descrição | P9: Entradas
B10: data | C10: topico | D10: sub-tópico | E10: descrição | F10: valor | H10: data | I10: Topico | J10: sub-tópico | K10: valor
B11: 46182 | C11: Investimento | E11: pc - processador | F11: 350 | I11: Parcelas | J11: mãe | K11: 1012.68
C12: Alimentação | F12: 3.58 | I12: Planos/assinaturas | J12: spotify já foi pago | K12: 14
C13: Lazer | F13: 11 | I13: Planos/assinaturas | J13: claro | K13: 30
C14: Despesas | F14: 15 | I14: Barbeiro | J14: barbeiro | K14: 35
C15: Lazer | F15: 1.8 | I15: Gasolina | J15: gasolina | K15: =10+80.02 -> 90.02
C16: Alimentação | F16: 24.17 | I16: Dizimos | J16: dizimo | K16: 210
C17: Imprevistos | F17: 26
C18: Despesas | F18: 6.66
C19: Transporte | F19: 12.99
C20: Alimentação | F20: 12.9
C21: Imprevistos | E21: marcelles | F21: 100
C22: Lazer | D22: Saídas com amigos | E22: jogo do brasil | F22: 42
F23: 23.9 | K23: =SUM(K11:K22) -> 1391.7
H24: terabyte | I24: SSD | J24: 1000
H25: Magalu | I25: RAM | J25: 1780
H26: amazon OU shoope | I26: MONITOR | J26: 560
H27: aliepres | I27: MOUSE | J27: 112
H28: pichau | I28: FONTE | J28: 499
H29: aliespres | I29: mousepad | J29: 40
H30: kabum | I30: TECLADO | J30: 350
H31: pichau | I31: COOLER | J31: 150
J32: =SUM(J24:J31) -> 4491
B35: Alimentação | C35: Doces | D35: =SUMIF($D$11:$D$32,C35,$F$11:$F$32) -> 0 | H35: Internet | I35: =SUMIF($I$11:$I$22,H35,$K$11:$K$22) -> 0
B36: =SUM(D35:D39) -> 0 | C36: Padaria | D36: =SUMIF($D$11:$D$32,C36,$F$11:$F$32) -> 0 | H36: Planos/assinaturas | I36: =SUMIF($I$11:$I$22,H36,$K$11:$K$22) -> 44
C37: Almoço fora | D37: =SUMIF($D$11:$D$32,C37,$F$11:$F$32) -> 0 | H37: Agua | I37: =SUMIF($I$11:$I$22,H37,$K$11:$K$22) -> 0
C38: Lanches / Snacks | D38: =SUMIF($D$11:$D$32,C38,$F$11:$F$32) -> 0 | H38: Luz | I38: =SUMIF($I$11:$I$22,H38,$K$11:$K$22) -> 0
D39: =SUMIF($D$11:$D$32,C39,$F$11:$F$32) -> 0 | H39: Gasolina | I39: =SUMIF($I$11:$I$22,H39,$K$11:$K$22) -> 90.02
H40: Dizimos | I40: =SUMIF($I$11:$I$22,H40,$K$11:$K$22) -> 210
B41: Lazer | C41: Delivery (iFood, etc) | D41: =SUMIF($D$11:$D$32,C41,$F$11:$F$32) -> 0 | H41: Ofertas | I41: =SUMIF($I$11:$I$22,H41,$K$11:$K$22) -> 0
B42: =SUBTOTAL(9,D41:D48) -> 42 | C42: Cinema / Shows | D42: =SUMIF($D$11:$D$32,C42,$F$11:$F$32) -> 0 | H42: Parcelas | I42: =SUMIF($I$11:$I$22,H42,$K$11:$K$22) -> 1012.68
C43: Passeios / Viagens | D43: =SUMIF($D$11:$D$32,C43,$F$11:$F$32) -> 0 | H43: Saúde | I43: =SUMIF($I$11:$I$22,H43,$K$11:$K$22) -> 0
C44: Compras por impulso (não essenciais) | D44: =SUMIF($D$11:$D$32,C44,$F$11:$F$32) -> 0 | H44: Investimento | I44: =SUMIF($I$11:$I$22,H44,$K$11:$K$22) -> 0
...

Sheet Jul
B2: JUL | C2: entradas | D2: valor | F2: Saldo mensal
B3: salário | D3: 2637 | E3: entradas | F3: =SUM(D3,D5,D6,D7,D4) -> 3291.25 | I3: data | K3: dinheiro guardado | L3: 809.19
B4: Fotografia | D4: =SUM(P10:P25) -> 366.25 | E4: gastos variados | F4: =SUM(F11:F32) -> 1736.43 | I4: =TODAY() -> 46242 | K4: dinheiro para inestimento futuro
B5: extra 2 | E5: entradas fotografia | F5: =D4 -> 366.25 | I5: ultimo update | K5: dinheiro para lente | L5: =SUM(P10:P25) -> 366.25
B6: extra 3 | E6: saidas fixas | F6: =SUM(K11:K22) -> 1357.68 | I6: 46233 | K6: para passar o mês, tenho => | L6: =217-SUM(F16:F32) -> -998.55
B7: Saldo | D7: =Jun!F7 -> 288 | E7: saldo | F7: =F3-F4-F6 -> 197.14
B9: Variados | H9: Fixos | M9: Eventos | N9: Data | O9: Descrição | P9: Entradas
B10: data | C10: topico | D10: sub-tópico | E10: descrição | F10: valor | H10: data | I10: Topico | J10: sub-tópico | K10: valor | M10: renovaocao dos votos | P10: 200
B11: 46209 | C11: Lazer | D11: Jogos / Games / Aplicativos pagos | E11: cartao | F11: 179.7 | I11: Gasolina | K11: 20 | M11: renovacao dos votos | P11: =200-33.75 -> 166.25
B12: 46210 | C12: Alimentação | D12: Padaria | E12: bugao | F12: 33.5 | I12: Parcelas | J12: mae | K12: 1012.68
C13: Despesas | D13: Gastos pessoais (roupas, acessórios) | F13: =19.5+3.68 -> 23.18 | I13: Barbeiro | K13: 35
C14: Lazer | D14: Saídas com amigos | E14: Sitio | F14: 100 | I14: Internet | K14: 30
C15: Despesas | D15: Gastos pessoais (roupas, acessórios) | E15: moletom e camisa | F15: 184.5 | I15: Dizimos | K15: 260
C16: Lazer | D16: Saídas com amigos | E16: espetinho | F16: 19
C17: Alimentação | D17: Padaria | F17: 25.9
C18: Transporte | D18: Manutenção (óleo, pneu, etc) | F18: 58
C19: Transporte | D19: Estacionamento | F19: 15
C20: Alimentação | D20: Padaria | F20: 3.8
C21: Despesas | D21: Presentes e datas comemorativas | F21: 120
C22: Despesas | D22: Presentes e datas comemorativas | F22: 18
C23: Alimentação | D23: Doces | F23: 21.85 | K23: =SUM(K11:K22) -> 1357.68
C24: Lazer | D24: Saídas com amigos | F24: 57.5
C25: Despesas | D25: Presentes e datas comemorativas | F25: 53
C26: Lazer | D26: Saídas com amigos | F26: 69
C27: Transporte | D27: Manutenção (óleo, pneu, etc) | F27: 750
F28: =4.5 -> 4.5
B35: Alimentação | C35: Doces | D35: =SUMIF($D$11:$D$32,C35,$F$11:$F$32) -> 21.85 | H35: Internet | I35: =SUMIF($I$11:$I$22,H35,$K$11:$K$22) -> 30
B36: =SUM(D35:D39) -> 85.05 | C36: Padaria | D36: =SUMIF($D$11:$D$32,C36,$F$11:$F$32) -> 63.2 | H36: Planos/assinaturas | I36: =SUMIF($I$11:$I$22,H36,$K$11:$K$22) -> 0
C37: Almoço fora | D37: =SUMIF($D$11:$D$32,C37,$F$11:$F$32) -> 0 | H37: Agua | I37: =SUMIF($I$11:$I$22,H37,$K$11:$K$22) -> 0
C38: Lanches / Snacks | D38: =SUMIF($D$11:$D$32,C38,$F$11:$F$32) -> 0 | H38: Luz | I38: =SUMIF($I$11:$I$22,H38,$K$11:$K$22) -> 0
D39: =SUMIF($D$11:$D$32,C39,$F$11:$F$32) -> 0 | H39: Gasolina | I39: =SUMIF($I$11:$I$22,H39,$K$11:$K$22) -> 20
H40: Dizimos | I40: =SUMIF($I$11:$I$22,H40,$K$11:$K$22) -> 260
B41: Lazer | C41: Delivery (iFood, etc) | D41: =SUMIF($D$11:$D$32,C41,$F$11:$F$32) -> 0 | H41: Ofertas | I41: =SUMIF($I$11:$I$22,H41,$K$11:$K$22) -> 0
B42: =SUBTOTAL(9,D41:D48) -> 245.5 | C42: Cinema / Shows | D42: =SUMIF($D$11:$D$32,C42,$F$11:$F$32) -> 0 | H42: Parcelas | I42: =SUMIF($I$11:$I$22,H42,$K$11:$K$22) -> 1012.68
C43: Passeios / Viagens | D43: =SUMIF($D$11:$D$32,C43,$F$11:$F$32) -> 0 | H43: Saúde | I43: =SUMIF($I$11:$I$22,H43,$K$11:$K$22) -> 0
C44: Compras por impulso (não essenciais) | D44: =SUMIF($D$11:$D$32,C44,$F$11:$F$32) -> 0 | H44: Investimento | I44: =SUMIF($I$11:$I$22,H44,$K$11:$K$22) -> 0
C45: Jogos / Games / Aplicativos pagos | D45: =SUMIF($D$11:$D$32,C45,$F$11:$F$32) -> 0 | I45: =SUMIF($I$11:$I$22,H45,$K$11:$K$22) -> 0
C46: Saídas com amigos | D46: =SUMIF($D$11:$D$32,C46,$F$11:$F$32) -> 245.5
D47: =SUMIF($D$11:$D$32,C47,$F$11:$F$32) -> 0
D48: =SUMIF($D$11:$D$32,C48,$F$11:$F$32) -> 0
...

Sheet Ago
B2: AGO | C2: entradas | D2: valor | F2: Saldo mensal
B3: salário | D3: 2540 | E3: entradas | F3: =SUM(D3,D5,D6,D7,D4) -> 2737.14 | I3: data | K3: dinheiro guardado | L3: 340
B4: Fotografia | D4: =SUM(P10:P25) -> 0 | E4: gastos variados | F4: =SUM(F11:F32) -> 312.67 | I4: =TODAY() -> 46242 | K4: dinheiro para inestimento futuro | L4: 522.75
B5: extra 2 | E5: entradas fotografia | F5: =D4 -> 0 | I5: ultimo update | K5: dinheiro para lente | L5: =SUM(P10:P25) -> 0
B6: extra 3 | E6: saidas fixas | F6: =SUM(K11:K22) -> 1416.36 | I6: 08.08 | K6: para passar o mês, tenho => | L6: =246-SUM(F15:F32) -> 246
B7: Saldo | D7: =Jul!F7 -> 197.14 | E7: saldo | F7: =F3-F4-F6 -> 1008.11
B9: Variados | H9: Fixos | M9: Eventos | N9: Data | O9: Descrição | P9: Entradas
B10: data | C10: topico | D10: sub-tópico | E10: descrição | F10: valor | H10: data | I10: Topico | J10: sub-tópico | K10: valor
C11: Lazer | D11: Esportes / saidas | F11: 20 | I11: Barbeiro | K11: 35
C12: Alimentação | F12: 4 | I12: Gasolina | K12: 72.66
C13: Despesas | D13: Compras online aleatórias | F13: 265.82 | I13: Parcelas | K13: 1012
C14: Lazer | D14: Esportes / saidas | F14: 22.85 | I14: Dizimos | K14: 250
I15: Internet | K15: 30
I16: Planos/assinaturas | K16: =10+6.7 -> 16.7
K23: =SUM(K11:K22) -> 1416.36
B35: Alimentação | C35: Doces | D35: =SUMIF($D$11:$D$32,C35,$F$11:$F$32) -> 0 | H35: Internet | I35: =SUMIF($I$11:$I$22,H35,$K$11:$K$22) -> 30
B36: =SUM(D35:D39) -> 0 | C36: Padaria | D36: =SUMIF($D$11:$D$32,C36,$F$11:$F$32) -> 0 | H36: Planos/assinaturas | I36: =SUMIF($I$11:$I$22,H36,$K$11:$K$22) -> 16.7
C37: Almoço fora | D37: =SUMIF($D$11:$D$32,C37,$F$11:$F$32) -> 0 | H37: Agua | I37: =SUMIF($I$11:$I$22,H37,$K$11:$K$22) -> 0
C38: Lanches / Snacks | D38: =SUMIF($D$11:$D$32,C38,$F$11:$F$32) -> 0 | H38: Luz | I38: =SUMIF($I$11:$I$22,H38,$K$11:$K$22) -> 0
D39: =SUMIF($D$11:$D$32,C39,$F$11:$F$32) -> 0 | H39: Gasolina | I39: =SUMIF($I$11:$I$22,H39,$K$11:$K$22) -> 72.66
H40: Dizimos | I40: =SUMIF($I$11:$I$22,H40,$K$11:$K$22) -> 250
B41: Lazer | C41: Delivery (iFood, etc) | D41: =SUMIF($D$11:$D$32,C41,$F$11:$F$32) -> 0 | H41: Ofertas | I41: =SUMIF($I$11:$I$22,H41,$K$11:$K$22) -> 0
B42: =SUBTOTAL(9,D41:D48) -> 0 | C42: Cinema / Shows | D42: =SUMIF($D$11:$D$32,C42,$F$11:$F$32) -> 0 | H42: Parcelas | I42: =SUMIF($I$11:$I$22,H42,$K$11:$K$22) -> 1012
C43: Passeios / Viagens | D43: =SUMIF($D$11:$D$32,C43,$F$11:$F$32) -> 0 | H43: Saúde | I43: =SUMIF($I$11:$I$22,H43,$K$11:$K$22) -> 0
C44: Compras por impulso (não essenciais) | D44: =SUMIF($D$11:$D$32,C44,$F$11:$F$32) -> 0 | H44: Investimento | I44: =SUMIF($I$11:$I$22,H44,$K$11:$K$22) -> 0
C45: Jogos / Games / Aplicativos pagos | D45: =SUMIF($D$11:$D$32,C45,$F$11:$F$32) -> 0 | I45: =SUMIF($I$11:$I$22,H45,$K$11:$K$22) -> 0
C46: Saídas com amigos | D46: =SUMIF($D$11:$D$32,C46,$F$11:$F$32) -> 0
D47: =SUMIF($D$11:$D$32,C47,$F$11:$F$32) -> 0
D48: =SUMIF($D$11:$D$32,C48,$F$11:$F$32) -> 0
B50: Despesas | C50: Presentes e datas comemorativas | D50: =SUMIF($D$11:$D$32,C50,$F$11:$F$32) -> 0
B51: =SUM(D50:D56) -> 265.82 | C51: Doações / Contribuições | D51: =SUMIF($D$11:$D$32,C51,$F$11:$F$32) -> 0
C52: Taxas bancárias / Pix por engano | D52: =SUMIF($D$11:$D$32,C52,$F$11:$F$32) -> 0
C53: Compras online aleatórias | D53: =SUMIF($D$11:$D$32,C53,$F$11:$F$32) -> 265.82
C54: Manutenção da casa (lâmpada, pilha, etc) | D54: =SUMIF($D$11:$D$32,C54,$F$11:$F$32) -> 0
C55: Gastos pessoais (roupas, acessórios) | D55: =SUMIF($D$11:$D$32,C55,$F$11:$F$32) -> 0
D56: =SUMIF($D$11:$D$32,C56,$F$11:$F$32) -> 0
B58: Transporte | C58: Acessório | D58: =SUMIF($D$11:$D$32,C58,$F$11:$F$32) -> 0
B59: =SUM(D58:D64) -> 0 | C59: Uber / Táxi | D59: =SUMIF($D$11:$D$32,C59,$F$11:$F$32) -> 0
C60: Ônibus / Metrô | D60: =SUMIF($D$11:$D$32,C60,$F$11:$F$32) -> 0
C61: Estacionamento | D61: =SUMIF($D$11:$D$32,C61,$F$11:$F$32) -> 0
...

Sheet Set
B2: SET | C2: entradas | D2: valor | F2: Saldo mensal
B3: salário | E3: entradas | F3: =SUM(D3,D5,D6,D7,D4) -> 1008.11 | I3: data | K3: dinheiro guardado
B4: Fotografia | D4: =SUM(P10:P25) -> 0 | E4: gastos variados | F4: =SUM(F11:F32) -> 0 | I4: =TODAY() -> 46242 | K4: dinheiro para inestimento futuro
B5: extra 2 | E5: entradas fotografia | F5: =D4 -> 0 | I5: ultimo update | K5: dinheiro para lente | L5: =SUM(P10:P25) -> 0
B6: extra 3 | E6: saidas fixas | F6: =SUM(K11:K22) -> 0 | I6: 45847 | K6: para passar o mês, tenho =>
B7: Saldo | D7: =Ago!F7 -> 1008.11 | E7: saldo | F7: =F3-F4-F6 -> 1008.11
B9: Variados | H9: Fixos | M9: Eventos | N9: Data | O9: Descrição | P9: Entradas
B10: data | C10: topico | D10: sub-tópico | E10: descrição | F10: valor | H10: data | I10: Topico | J10: sub-tópico | K10: valor
K23: =SUM(K11:K22) -> 0
B35: Alimentação | C35: Doces | D35: =SUMIF($D$11:$D$32,C35,$F$11:$F$32) -> 0 | H35: Internet | I35: =SUMIF($I$11:$I$22,H35,$K$11:$K$22) -> 0
B36: =SUM(D35:D39) -> 0 | C36: Padaria | D36: =SUMIF($D$11:$D$32,C36,$F$11:$F$32) -> 0 | H36: Planos/assinaturas | I36: =SUMIF($I$11:$I$22,H36,$K$11:$K$22) -> 0
C37: Almoço fora | D37: =SUMIF($D$11:$D$32,C37,$F$11:$F$32) -> 0 | H37: Agua | I37: =SUMIF($I$11:$I$22,H37,$K$11:$K$22) -> 0
C38: Lanches / Snacks | D38: =SUMIF($D$11:$D$32,C38,$F$11:$F$32) -> 0 | H38: Luz | I38: =SUMIF($I$11:$I$22,H38,$K$11:$K$22) -> 0
D39: =SUMIF($D$11:$D$32,C39,$F$11:$F$32) -> 0 | H39: Gasolina | I39: =SUMIF($I$11:$I$22,H39,$K$11:$K$22) -> 0
H40: Dizimos | I40: =SUMIF($I$11:$I$22,H40,$K$11:$K$22) -> 0
B41: Lazer | C41: Delivery (iFood, etc) | D41: =SUMIF($D$11:$D$32,C41,$F$11:$F$32) -> 0 | H41: Ofertas | I41: =SUMIF($I$11:$I$22,H41,$K$11:$K$22) -> 0
B42: =SUBTOTAL(9,D41:D48) -> 0 | C42: Cinema / Shows | D42: =SUMIF($D$11:$D$32,C42,$F$11:$F$32) -> 0 | H42: Parcelas | I42: =SUMIF($I$11:$I$22,H42,$K$11:$K$22) -> 0
C43: Passeios / Viagens | D43: =SUMIF($D$11:$D$32,C43,$F$11:$F$32) -> 0 | H43: Saúde | I43: =SUMIF($I$11:$I$22,H43,$K$11:$K$22) -> 0
C44: Compras por impulso (não essenciais) | D44: =SUMIF($D$11:$D$32,C44,$F$11:$F$32) -> 0 | H44: Investimento | I44: =SUMIF($I$11:$I$22,H44,$K$11:$K$22) -> 0
C45: Jogos / Games / Aplicativos pagos | D45: =SUMIF($D$11:$D$32,C45,$F$11:$F$32) -> 0 | I45: =SUMIF($I$11:$I$22,H45,$K$11:$K$22) -> 0
C46: Saídas com amigos | D46: =SUMIF($D$11:$D$32,C46,$F$11:$F$32) -> 0
D47: =SUMIF($D$11:$D$32,C47,$F$11:$F$32) -> 0
D48: =SUMIF($D$11:$D$32,C48,$F$11:$F$32) -> 0
B50: Despesas | C50: Presentes e datas comemorativas | D50: =SUMIF($D$11:$D$32,C50,$F$11:$F$32) -> 0
B51: =SUM(D50:D56) -> 0 | C51: Doações / Contribuições | D51: =SUMIF($D$11:$D$32,C51,$F$11:$F$32) -> 0
C52: Taxas bancárias / Pix por engano | D52: =SUMIF($D$11:$D$32,C52,$F$11:$F$32) -> 0
C53: Compras online aleatórias | D53: =SUMIF($D$11:$D$32,C53,$F$11:$F$32) -> 0
C54: Manutenção da casa (lâmpada, pilha, etc) | D54: =SUMIF($D$11:$D$32,C54,$F$11:$F$32) -> 0
C55: Gastos pessoais (roupas, acessórios) | D55: =SUMIF($D$11:$D$32,C55,$F$11:$F$32) -> 0
D56: =SUMIF($D$11:$D$32,C56,$F$11:$F$32) -> 0
B58: Transporte | C58: Acessório | D58: =SUMIF($D$11:$D$32,C58,$F$11:$F$32) -> 0
B59: =SUM(D58:D64) -> 0 | C59: Uber / Táxi | D59: =SUMIF($D$11:$D$32,C59,$F$11:$F$32) -> 0
C60: Ônibus / Metrô | D60: =SUMIF($D$11:$D$32,C60,$F$11:$F$32) -> 0
C61: Estacionamento | D61: =SUMIF($D$11:$D$32,C61,$F$11:$F$32) -> 0
C62: Manutenção (óleo, pneu, etc) | D62: =SUMIF($D$11:$D$32,C62,$F$11:$F$32) -> 0
C63: Multas / Documentação | D63: =SUMIF($D$11:$D$32,C63,$F$11:$F$32) -> 0
D64: =SUMIF($D$11:$D$32,C64,$F$11:$F$32) -> 0
B66: Educação | C66: Livros | D66: =SUMIF($D$11:$D$32,C66,$F$11:$F$32) -> 0
B67: =SUM(D66:D72) -> 0 | C67: Cursos online (Udemy, Alura, etc) | D67: =SUMIF($D$11:$D$32,C67,$F$11:$F$32) -> 0
C68: Material escolar / didático | D68: =SUMIF($D$11:$D$32,C68,$F$11:$F$32) -> 0
...

Sheet Out
B2: OUT | C2: entradas | D2: valor | F2: Saldo mensal
B3: salário | E3: entradas | F3: =SUM(D3,D5,D6,D7,D4) -> 1008.11 | I3: data | K3: dinheiro guardado
B4: Fotografia | D4: =SUM(P10:P25) -> 0 | E4: gastos variados | F4: =SUM(F11:F32) -> 0 | I4: =TODAY() -> 46242 | K4: dinheiro para inestimento futuro
B5: extra 2 | E5: entradas fotografia | F5: =D4 -> 0 | I5: ultimo update | K5: dinheiro para lente | L5: =SUM(P10:P25) -> 0
B6: extra 3 | E6: saidas fixas | F6: =SUM(K11:K22) -> 0 | I6: 45847 | K6: para passar o mês, tenho =>
B7: Saldo | D7: =Set!F7 -> 1008.11 | E7: saldo | F7: =F3-F4-F6 -> 1008.11
B9: Variados | H9: Fixos | M9: Eventos | N9: Data | O9: Descrição | P9: Entradas
B10: data | C10: topico | D10: sub-tópico | E10: descrição | F10: valor | H10: data | I10: Topico | J10: sub-tópico | K10: valor
K23: =SUM(K11:K22) -> 0
B35: Alimentação | C35: Doces | D35: =SUMIF($D$11:$D$32,C35,$F$11:$F$32) -> 0 | H35: Internet | I35: =SUMIF($I$11:$I$22,H35,$K$11:$K$22) -> 0
B36: =SUM(D35:D39) -> 0 | C36: Padaria | D36: =SUMIF($D$11:$D$32,C36,$F$11:$F$32) -> 0 | H36: Planos/assinaturas | I36: =SUMIF($I$11:$I$22,H36,$K$11:$K$22) -> 0
C37: Almoço fora | D37: =SUMIF($D$11:$D$32,C37,$F$11:$F$32) -> 0 | H37: Agua | I37: =SUMIF($I$11:$I$22,H37,$K$11:$K$22) -> 0
C38: Lanches / Snacks | D38: =SUMIF($D$11:$D$32,C38,$F$11:$F$32) -> 0 | H38: Luz | I38: =SUMIF($I$11:$I$22,H38,$K$11:$K$22) -> 0
D39: =SUMIF($D$11:$D$32,C39,$F$11:$F$32) -> 0 | H39: Gasolina | I39: =SUMIF($I$11:$I$22,H39,$K$11:$K$22) -> 0
H40: Dizimos | I40: =SUMIF($I$11:$I$22,H40,$K$11:$K$22) -> 0
B41: Lazer | C41: Delivery (iFood, etc) | D41: =SUMIF($D$11:$D$32,C41,$F$11:$F$32) -> 0 | H41: Ofertas | I41: =SUMIF($I$11:$I$22,H41,$K$11:$K$22) -> 0
B42: =SUBTOTAL(9,D41:D48) -> 0 | C42: Cinema / Shows | D42: =SUMIF($D$11:$D$32,C42,$F$11:$F$32) -> 0 | H42: Parcelas | I42: =SUMIF($I$11:$I$22,H42,$K$11:$K$22) -> 0
C43: Passeios / Viagens | D43: =SUMIF($D$11:$D$32,C43,$F$11:$F$32) -> 0 | H43: Saúde | I43: =SUMIF($I$11:$I$22,H43,$K$11:$K$22) -> 0
C44: Compras por impulso (não essenciais) | D44: =SUMIF($D$11:$D$32,C44,$F$11:$F$32) -> 0 | H44: Investimento | I44: =SUMIF($I$11:$I$22,H44,$K$11:$K$22) -> 0
C45: Jogos / Games / Aplicativos pagos | D45: =SUMIF($D$11:$D$32,C45,$F$11:$F$32) -> 0 | I45: =SUMIF($I$11:$I$22,H45,$K$11:$K$22) -> 0
C46: Saídas com amigos | D46: =SUMIF($D$11:$D$32,C46,$F$11:$F$32) -> 0
D47: =SUMIF($D$11:$D$32,C47,$F$11:$F$32) -> 0
D48: =SUMIF($D$11:$D$32,C48,$F$11:$F$32) -> 0
B50: Despesas | C50: Presentes e datas comemorativas | D50: =SUMIF($D$11:$D$32,C50,$F$11:$F$32) -> 0
B51: =SUM(D50:D56) -> 0 | C51: Doações / Contribuições | D51: =SUMIF($D$11:$D$32,C51,$F$11:$F$32) -> 0
C52: Taxas bancárias / Pix por engano | D52: =SUMIF($D$11:$D$32,C52,$F$11:$F$32) -> 0
C53: Compras online aleatórias | D53: =SUMIF($D$11:$D$32,C53,$F$11:$F$32) -> 0
C54: Manutenção da casa (lâmpada, pilha, etc) | D54: =SUMIF($D$11:$D$32,C54,$F$11:$F$32) -> 0
C55: Gastos pessoais (roupas, acessórios) | D55: =SUMIF($D$11:$D$32,C55,$F$11:$F$32) -> 0
D56: =SUMIF($D$11:$D$32,C56,$F$11:$F$32) -> 0
B58: Transporte | C58: Acessório | D58: =SUMIF($D$11:$D$32,C58,$F$11:$F$32) -> 0
B59: =SUM(D58:D64) -> 0 | C59: Uber / Táxi | D59: =SUMIF($D$11:$D$32,C59,$F$11:$F$32) -> 0
C60: Ônibus / Metrô | D60: =SUMIF($D$11:$D$32,C60,$F$11:$F$32) -> 0
C61: Estacionamento | D61: =SUMIF($D$11:$D$32,C61,$F$11:$F$32) -> 0
C62: Manutenção (óleo, pneu, etc) | D62: =SUMIF($D$11:$D$32,C62,$F$11:$F$32) -> 0
C63: Multas / Documentação | D63: =SUMIF($D$11:$D$32,C63,$F$11:$F$32) -> 0
D64: =SUMIF($D$11:$D$32,C64,$F$11:$F$32) -> 0
B66: Educação | C66: Livros | D66: =SUMIF($D$11:$D$32,C66,$F$11:$F$32) -> 0
B67: =SUM(D66:D72) -> 0 | C67: Cursos online (Udemy, Alura, etc) | D67: =SUMIF($D$11:$D$32,C67,$F$11:$F$32) -> 0
C68: Material escolar / didático | D68: =SUMIF($D$11:$D$32,C68,$F$11:$F$32) -> 0
...

Sheet Nov
B2: NOV | C2: entradas | D2: valor | F2: Saldo mensal
B3: salário | E3: entradas | F3: =SUM(D3,D5,D6,D7,D4) -> 1008.11 | I3: data | K3: dinheiro guardado
B4: Fotografia | D4: =SUM(P10:P25) -> 0 | E4: gastos variados | F4: =SUM(F11:F32) -> 0 | I4: =TODAY() -> 46242 | K4: dinheiro para inestimento futuro
B5: extra 2 | E5: entradas fotografia | F5: =D4 -> 0 | I5: ultimo update | K5: dinheiro para lente | L5: =SUM(P10:P25) -> 0
B6: extra 3 | E6: saidas fixas | F6: =SUM(K11:K22) -> 0 | I6: 45847 | K6: para passar o mês, tenho =>
B7: Saldo | D7: =Out!F7 -> 1008.11 | E7: saldo | F7: =F3-F4-F6 -> 1008.11
B9: Variados | H9: Fixos | M9: Eventos | N9: Data | O9: Descrição | P9: Entradas
B10: data | C10: topico | D10: sub-tópico | E10: descrição | F10: valor | H10: data | I10: Topico | J10: sub-tópico | K10: valor
K23: =SUM(K11:K22) -> 0
B35: Alimentação | C35: Doces | D35: =SUMIF($D$11:$D$32,C35,$F$11:$F$32) -> 0 | H35: Internet | I35: =SUMIF($I$11:$I$22,H35,$K$11:$K$22) -> 0
B36: =SUM(D35:D39) -> 0 | C36: Padaria | D36: =SUMIF($D$11:$D$32,C36,$F$11:$F$32) -> 0 | H36: Planos/assinaturas | I36: =SUMIF($I$11:$I$22,H36,$K$11:$K$22) -> 0
C37: Almoço fora | D37: =SUMIF($D$11:$D$32,C37,$F$11:$F$32) -> 0 | H37: Agua | I37: =SUMIF($I$11:$I$22,H37,$K$11:$K$22) -> 0
C38: Lanches / Snacks | D38: =SUMIF($D$11:$D$32,C38,$F$11:$F$32) -> 0 | H38: Luz | I38: =SUMIF($I$11:$I$22,H38,$K$11:$K$22) -> 0
D39: =SUMIF($D$11:$D$32,C39,$F$11:$F$32) -> 0 | H39: Gasolina | I39: =SUMIF($I$11:$I$22,H39,$K$11:$K$22) -> 0
H40: Dizimos | I40: =SUMIF($I$11:$I$22,H40,$K$11:$K$22) -> 0
B41: Lazer | C41: Delivery (iFood, etc) | D41: =SUMIF($D$11:$D$32,C41,$F$11:$F$32) -> 0 | H41: Ofertas | I41: =SUMIF($I$11:$I$22,H41,$K$11:$K$22) -> 0
B42: =SUBTOTAL(9,D41:D48) -> 0 | C42: Cinema / Shows | D42: =SUMIF($D$11:$D$32,C42,$F$11:$F$32) -> 0 | H42: Parcelas | I42: =SUMIF($I$11:$I$22,H42,$K$11:$K$22) -> 0
C43: Passeios / Viagens | D43: =SUMIF($D$11:$D$32,C43,$F$11:$F$32) -> 0 | H43: Saúde | I43: =SUMIF($I$11:$I$22,H43,$K$11:$K$22) -> 0
C44: Compras por impulso (não essenciais) | D44: =SUMIF($D$11:$D$32,C44,$F$11:$F$32) -> 0 | H44: Investimento | I44: =SUMIF($I$11:$I$22,H44,$K$11:$K$22) -> 0
C45: Jogos / Games / Aplicativos pagos | D45: =SUMIF($D$11:$D$32,C45,$F$11:$F$32) -> 0 | I45: =SUMIF($I$11:$I$22,H45,$K$11:$K$22) -> 0
C46: Saídas com amigos | D46: =SUMIF($D$11:$D$32,C46,$F$11:$F$32) -> 0
D47: =SUMIF($D$11:$D$32,C47,$F$11:$F$32) -> 0
D48: =SUMIF($D$11:$D$32,C48,$F$11:$F$32) -> 0
B50: Despesas | C50: Presentes e datas comemorativas | D50: =SUMIF($D$11:$D$32,C50,$F$11:$F$32) -> 0
B51: =SUM(D50:D56) -> 0 | C51: Doações / Contribuições | D51: =SUMIF($D$11:$D$32,C51,$F$11:$F$32) -> 0
C52: Taxas bancárias / Pix por engano | D52: =SUMIF($D$11:$D$32,C52,$F$11:$F$32) -> 0
C53: Compras online aleatórias | D53: =SUMIF($D$11:$D$32,C53,$F$11:$F$32) -> 0
C54: Manutenção da casa (lâmpada, pilha, etc) | D54: =SUMIF($D$11:$D$32,C54,$F$11:$F$32) -> 0
C55: Gastos pessoais (roupas, acessórios) | D55: =SUMIF($D$11:$D$32,C55,$F$11:$F$32) -> 0
D56: =SUMIF($D$11:$D$32,C56,$F$11:$F$32) -> 0
B58: Transporte | C58: Acessório | D58: =SUMIF($D$11:$D$32,C58,$F$11:$F$32) -> 0
B59: =SUM(D58:D64) -> 0 | C59: Uber / Táxi | D59: =SUMIF($D$11:$D$32,C59,$F$11:$F$32) -> 0
C60: Ônibus / Metrô | D60: =SUMIF($D$11:$D$32,C60,$F$11:$F$32) -> 0
C61: Estacionamento | D61: =SUMIF($D$11:$D$32,C61,$F$11:$F$32) -> 0
C62: Manutenção (óleo, pneu, etc) | D62: =SUMIF($D$11:$D$32,C62,$F$11:$F$32) -> 0
C63: Multas / Documentação | D63: =SUMIF($D$11:$D$32,C63,$F$11:$F$32) -> 0
D64: =SUMIF($D$11:$D$32,C64,$F$11:$F$32) -> 0
B66: Educação | C66: Livros | D66: =SUMIF($D$11:$D$32,C66,$F$11:$F$32) -> 0
B67: =SUM(D66:D72) -> 0 | C67: Cursos online (Udemy, Alura, etc) | D67: =SUMIF($D$11:$D$32,C67,$F$11:$F$32) -> 0
C68: Material escolar / didático | D68: =SUMIF($D$11:$D$32,C68,$F$11:$F$32) -> 0
...

Sheet Dez
B2: DEZ | C2: entradas | D2: valor | F2: Saldo mensal
B3: salário | E3: entradas | F3: =SUM(D3,D5,D6,D7,D4) -> 1008.11 | I3: data | K3: dinheiro guardado
B4: Fotografia | D4: =SUM(P10:P25) -> 0 | E4: gastos variados | F4: =SUM(F11:F32) -> 0 | I4: =TODAY() -> 46242 | K4: dinheiro para inestimento futuro
B5: extra 2 | E5: entradas fotografia | F5: =D4 -> 0 | I5: ultimo update | K5: dinheiro para lente | L5: =SUM(P10:P25) -> 0
B6: extra 3 | E6: saidas fixas | F6: =SUM(K11:K22) -> 0 | I6: 46002 | K6: para passar o mês, tenho =>
B7: Saldo | D7: =Nov!F7 -> 1008.11 | E7: saldo | F7: =F3-F4-F6 -> 1008.11
B9: Variados | H9: Fixos | M9: Eventos | N9: Data | O9: Descrição | P9: Entradas
B10: data | C10: topico | D10: sub-tópico | E10: descrição | F10: valor | H10: data | I10: Topico | J10: sub-tópico | K10: valor
K23: =SUM(K11:K22) -> 0
B35: Alimentação | C35: Doces | D35: =SUMIF($D$11:$D$32,C35,$F$11:$F$32) -> 0 | H35: Internet | I35: =SUMIF($I$11:$I$22,H35,$K$11:$K$22) -> 0
B36: =SUM(D35:D39) -> 0 | C36: Padaria | D36: =SUMIF($D$11:$D$32,C36,$F$11:$F$32) -> 0 | H36: Planos/assinaturas | I36: =SUMIF($I$11:$I$22,H36,$K$11:$K$22) -> 0
C37: Almoço fora | D37: =SUMIF($D$11:$D$32,C37,$F$11:$F$32) -> 0 | H37: Agua | I37: =SUMIF($I$11:$I$22,H37,$K$11:$K$22) -> 0
C38: Lanches / Snacks | D38: =SUMIF($D$11:$D$32,C38,$F$11:$F$32) -> 0 | H38: Luz | I38: =SUMIF($I$11:$I$22,H38,$K$11:$K$22) -> 0
D39: =SUMIF($D$11:$D$32,C39,$F$11:$F$32) -> 0 | H39: Gasolina | I39: =SUMIF($I$11:$I$22,H39,$K$11:$K$22) -> 0
H40: Dizimos | I40: =SUMIF($I$11:$I$22,H40,$K$11:$K$22) -> 0
B41: Lazer | C41: Delivery (iFood, etc) | D41: =SUMIF($D$11:$D$32,C41,$F$11:$F$32) -> 0 | H41: Ofertas | I41: =SUMIF($I$11:$I$22,H41,$K$11:$K$22) -> 0
B42: =SUBTOTAL(9,D41:D48) -> 0 | C42: Cinema / Shows | D42: =SUMIF($D$11:$D$32,C42,$F$11:$F$32) -> 0 | H42: Parcelas | I42: =SUMIF($I$11:$I$22,H42,$K$11:$K$22) -> 0
C43: Passeios / Viagens | D43: =SUMIF($D$11:$D$32,C43,$F$11:$F$32) -> 0 | H43: Saúde | I43: =SUMIF($I$11:$I$22,H43,$K$11:$K$22) -> 0
C44: Compras por impulso (não essenciais) | D44: =SUMIF($D$11:$D$32,C44,$F$11:$F$32) -> 0 | H44: Investimento | I44: =SUMIF($I$11:$I$22,H44,$K$11:$K$22) -> 0
C45: Jogos / Games / Aplicativos pagos | D45: =SUMIF($D$11:$D$32,C45,$F$11:$F$32) -> 0 | I45: =SUMIF($I$11:$I$22,H45,$K$11:$K$22) -> 0
C46: Saídas com amigos | D46: =SUMIF($D$11:$D$32,C46,$F$11:$F$32) -> 0
D47: =SUMIF($D$11:$D$32,C47,$F$11:$F$32) -> 0
D48: =SUMIF($D$11:$D$32,C48,$F$11:$F$32) -> 0
B50: Despesas | C50: Presentes e datas comemorativas | D50: =SUMIF($D$11:$D$32,C50,$F$11:$F$32) -> 0
B51: =SUM(D50:D56) -> 0 | C51: Doações / Contribuições | D51: =SUMIF($D$11:$D$32,C51,$F$11:$F$32) -> 0
C52: Taxas bancárias / Pix por engano | D52: =SUMIF($D$11:$D$32,C52,$F$11:$F$32) -> 0
C53: Compras online aleatórias | D53: =SUMIF($D$11:$D$32,C53,$F$11:$F$32) -> 0
C54: Manutenção da casa (lâmpada, pilha, etc) | D54: =SUMIF($D$11:$D$32,C54,$F$11:$F$32) -> 0
C55: Gastos pessoais (roupas, acessórios) | D55: =SUMIF($D$11:$D$32,C55,$F$11:$F$32) -> 0
D56: =SUMIF($D$11:$D$32,C56,$F$11:$F$32) -> 0
B58: Transporte | C58: Acessório | D58: =SUMIF($D$11:$D$32,C58,$F$11:$F$32) -> 0
B59: =SUM(D58:D64) -> 0 | C59: Uber / Táxi | D59: =SUMIF($D$11:$D$32,C59,$F$11:$F$32) -> 0
C60: Ônibus / Metrô | D60: =SUMIF($D$11:$D$32,C60,$F$11:$F$32) -> 0
C61: Estacionamento | D61: =SUMIF($D$11:$D$32,C61,$F$11:$F$32) -> 0
C62: Manutenção (óleo, pneu, etc) | D62: =SUMIF($D$11:$D$32,C62,$F$11:$F$32) -> 0
C63: Multas / Documentação | D63: =SUMIF($D$11:$D$32,C63,$F$11:$F$32) -> 0
D64: =SUMIF($D$11:$D$32,C64,$F$11:$F$32) -> 0
B66: Educação | C66: Livros | D66: =SUMIF($D$11:$D$32,C66,$F$11:$F$32) -> 0
B67: =SUM(D66:D72) -> 0 | C67: Cursos online (Udemy, Alura, etc) | D67: =SUMIF($D$11:$D$32,C67,$F$11:$F$32) -> 0
C68: Material escolar / didático | D68: =SUMIF($D$11:$D$32,C68,$F$11:$F$32) -> 0
...

Sheet Anual
B2: SUB-TOTAIS | C2: Jan | D2: Fev | E2: Mar | F2: Abr | G2: Mai | H2: Jun | I2: Jul | J2: Ago | K2: Set | L2: Out | M2: Nov | N2: Dez | O2: total
B3: Entradas | C3: =Jan!$F$3 -> 2246.57 | D3: =Fev!$F$3 -> 2281.55 | E3: =Mar!$F$3 -> 2080.77 | F3: =Abr!$F$3 -> 2679.04 | G3: =Mai!$F$3 -> 4523.74 | H3: =Jun!$F$3 -> 2309.7 | I3: =Jul!$F$3 -> 3291.25 | J3: =Ago!$F$3 -> 2737.14 | K3: =Set!$F$3 -> 1008.11 | L3: =Out!$F$3 -> 1008.11 | M3: =Nov!$F$3 -> 1008.11 | N3: =Dez!$F$3 -> 1008.11 | O3: =SUM(C3:N3) -> 26182.2
B4: Saidas Variáveis | C4: =Jan!$F$4 -> 568.02 | D4: =Fev!$F$4 -> 561.58 | E4: =Mar!$F$4 -> 1203.63 | F4: =Abr!$F$4 -> 723.11 | G4: =Mai!$F$4 -> 3935.01 | H4: =Jun!$F$4 -> 630 | I4: =Jul!$F$4 -> 1736.43 | J4: =Ago!$F$4 -> 312.67 | K4: =Set!$F$4 -> 0 | L4: =Out!$F$4 -> 0 | M4: =Nov!$F$4 -> 0 | N4: =Dez!$F$4 -> 0 | O4: =SUM(C4:N4) -> 9670.45
B5: Saidas Fixas | C5: =Jan!$F$6 -> 337 | D5: =Fev!$F$6 -> 362.2 | E5: =Mar!$F$6 -> 434.6 | F5: =Abr!$F$6 -> 516.69 | G5: =Mai!$F$6 -> 597.03 | H5: =Jun!$F$6 -> 1391.7 | I5: =Jul!$F$6 -> 1357.68 | J5: =Ago!$F$6 -> 1416.36 | K5: =Set!$F$6 -> 0 | L5: =Out!$F$6 -> 0 | M5: =Nov!$F$6 -> 0 | N5: =Dez!$F$6 -> 0 | O5: =SUM(C5:N5) -> 6413.26
B6: dinheiro guardado | C6: =Jan!$L$3 -> 0 | D6: =Fev!$L$3 -> 0 | E6: =Mar!$L$3 -> 0 | F6: =Abr!$L$3 -> 1343 | G6: =Mai!$L$3 -> 2503 | H6: =Jun!$L$3 -> 200 | I6: =Jul!$L$3 -> 809.19 | J6: =Ago!$L$3 -> 340 | K6: =Set!$L$3 -> 0 | L6: =Out!$L$3 -> 0 | M6: =Nov!$L$3 -> 0 | N6: =Dez!$L$3 -> 0 | O6: =SUM(C6:N6) -> 5195.19
B7: dinheiro para investimentos | C7: =Jan!$L$4 -> 0 | D7: =Fev!$L$4 -> 0 | E7: =Mar!$L$4 -> 0 | F7: =Abr!$L$4 -> 983.93 | G7: =Mai!$L$4 -> 0 | H7: =Jun!$L$4 -> 0 | I7: =Jul!$L$4 -> 0 | J7: =Ago!$L$4 -> 522.75 | K7: =Set!$L$4 -> 0 | L7: =Out!$L$4 -> 0 | M7: =Nov!$L$4 -> 0 | N7: =Dez!$L$4 -> 0 | O7: =SUM(C7:N7) -> 1506.68
B8: Saidas Totais | C8: =C4+C5 -> 905.02 | D8: =D4+D5 -> 923.78 | E8: =E4+E5 -> 1638.23 | F8: =F4+F5 -> 1239.8 | G8: =G4+G5 -> 4532.04 | H8: =H4+H5 -> 2021.7 | I8: =I4+I5 -> 3094.11 | J8: =J4+J5 -> 1729.03 | ... N8: =N4+N5 -> 0 | O8: =SUM(C8:N8) -> 16083.71
B9: Saldo | C9: =C3-C8 -> 1341.55 | D9: =D3-D8 -> 1357.77 | E9: =E3-E8 -> 442.54 | F9: =F3-F8 -> 1439.24 | G9: =G3-G8 -> -8.3 | H9: =H3-H8 -> 288 | I9: =I3-I8 -> 197.14 | J9: =J3-J8 -> 1008.11 | ... N9: =N3-N8 -> 1008.11 | O9: =N9 -> 1008.11
B10: Fotografia | C10: =Jan!D4 -> 103.33 | D10: =Fev!D4 -> 200 | E10: =Mar!D4 -> 0 | F10: =Abr!D4 -> 136.5 | G10: =Mai!D4 -> 20 | H10: =Jun!D4 -> 0 | I10: =Jul!D4 -> 366.25 | J10: =Ago!D4 -> 0 | K10: =Set!D4 -> 0 | L10: =Out!D4 -> 0 | M10: =Nov!D4 -> 0 | N10: =Dez!D4 -> 0 | O10: =SUM(C10:N10) -> 826.08
L13: =12*25.82 -> 309.84
B15: SUB-TOTAIS | C15: Jan | D15: Fev | E15: Mar | F15: Abr | G15: Mai | H15: Jun | I15: Jul | J15: Ago | K15: Set | L15: Out | M15: Nov | N15: Dez | O15: TOTAL
B16: Alimentação | C16: =Jan!$B$36 -> 0 | D16: =Fev!$B$36 -> 0 | E16: =Mar!$B$36 -> 12 | F16: =Abr!$B$36 -> 79.46 | G16: =Mai!$B$36 -> 0 | H16: =Jun!$B$36 -> 0 | I16: =Jul!$B$36 -> 85.05 | J16: =Ago!$B$36 -> 0 | K16: =Set!$B$36 -> 0 | L16: =Out!$B$36 -> 0 | M16: =Nov!$B$36 -> 0 | N16: =Dez!$B$36 -> 0 | O16: =SUM(C16:N16) -> 176.51
B17: Lazer | C17: =Jan!$B$42 -> 23.69 | D17: =Fev!$B$42 -> 39 | E17: =Mar!$B$42 -> 47.88 | F17: =Abr!$B$42 -> 190.31 | G17: =Mai!$B$42 -> 69.7 | H17: =Jun!$B$42 -> 42 | I17: =Jul!$B$42 -> 245.5 | J17: =Ago!$B$42 -> 0 | K17: =Set!$B$42 -> 0 | L17: =Out!$B$42 -> 0 | M17: =Nov!$B$42 -> 0 | N17: =Dez!$B$42 -> 0 | O17: =SUM(C17:N17) -> 658.08
B18: Despesas | C18: =Jan!$B$51 -> 93.95 | D18: =Fev!B51 -> 226.24 | E18: =Mar!$B$51 -> 19.3 | F18: =Abr!$B$51 -> 153.2 | G18: =Mai!$B$51 -> 76.9 | H18: =Jun!$B$51 -> 0 | I18: =Jul!$B$51 -> 398.68 | J18: =Ago!$B$51 -> 265.82 | K18: =Set!$B$51 -> 0 | L18: =Out!$B$51 -> 0 | M18: =Nov!$B$51 -> 0 | N18: =Dez!$B$51 -> 0 | O18: =SUM(C18:N18) -> 1234.09
B19: Transporte | C19: =Jan!$B$59 -> 72 | D19: =Fev!$B$59 -> 296.34 | E19: =Mar!$B$59 -> 210 | F19: =Abr!$B$59 -> 48.5 | G19: =Mai!$B$59 -> 48 | H19: =Jun!$B$59 -> 0 | I19: =Jul!$B$59 -> 823 | J19: =Ago!$B$59 -> 0 | K19: =Set!$B$59 -> 0 | L19: =Out!$B$59 -> 0 | M19: =Nov!$B$59 -> 0 | N19: =Dez!$B$59 -> 0 | O19: =SUM(C19:N19) -> 1497.84
B20: Educação | C20: =Jan!$B$67 -> 0 | D20: =Fev!$B$67 -> 0 | E20: =Mar!$B$67 -> 34.45 | F20: =Abr!$B$67 -> 0 | G20: =Mai!$B$67 -> 0 | H20: =Jun!$B$67 -> 0 | I20: =Jul!$B$67 -> 0 | J20: =Ago!$B$67 -> 0 | K20: =Set!$B$67 -> 0 | L20: =Out!$B$67 -> 0 | M20: =Nov!$B$67 -> 0 | N20: =Dez!$B$67 -> 0 | O20: =SUM(C20:N20) -> 34.45
B21: Saúde | C21: =Jan!$B$75 -> 0 | D21: =Fev!$B$75 -> 0 | E21: =Mar!$B$75 -> 0 | F21: =Abr!$B$75 -> 0 | G21: =Mai!$B$75 -> 0 | H21: =Jun!$B$75 -> 0 | I21: =Jul!$B$75 -> 0 | J21: =Ago!$B$75 -> 0 | K21: =Set!$B$75 -> 0 | L21: =Out!$B$75 -> 0 | M21: =Nov!$B$75 -> 0 | N21: =Dez!$B$75 -> 0 | O21: =SUM(C21:N21) -> 0
B22: Investimento | C22: =Jan!$D$90 -> 0 | D22: =Fev!$D$90 -> 0 | E22: =Mar!$D$90 -> 0 | F22: =Abr!$D$90 -> 201.64 | G22: =Mai!$D$90 -> 5548.69 | H22: =Jun!$D$90 -> 350 | I22: =Jul!$D$90 -> 0 | J22: =Ago!$D$90 -> 0 | K22: =Set!$D$90 -> 0 | L22: =Out!$D$90 -> 0 | M22: =Nov!$D$90 -> 0 | N22: =Dez!$D$90 -> 0
B23: Imprevistos | C23: =Jan!$B$83 -> 0 | D23: =Fev!$B$83 -> 0 | E23: =Mar!$B$83 -> 880 | F23: =Abr!$B$83 -> 50 | G23: =Mai!$B$83 -> 0 | H23: =Jun!$B$83 -> 0 | I23: =Jul!$B$83 -> 0 | J23: =Ago!$B$83 -> 0 | K23: =Set!$B$83 -> 0 | L23: =Out!$B$83 -> 0 | M23: =Nov!$B$83 -> 0 | N23: =Dez!$B$83 -> 0 | O23: =SUM(C23:N23) -> 930
B27: Alimentação | C27: Doces | D27: =SUBTOTAL(9,Fev!D35,Fev!D35,Mar!D35,Abr!D35,Mai!D35,Jun!D35,Jul!D35,Ago!D35,Set!D35,Out!D35,Nov!D35,Dez!D35) -> 45.21
B28: =SUM(D27:D31) -> 176.51 | C28: Padaria | D28: =SUBTOTAL(9,Fev!D36,Fev!D36,Mar!D36,Abr!D36,Mai!D36,Jun!D36,Jul!D36,Ago!D36,Set!D36,Out!D36,Nov!D36,Dez!D36) -> 131.3 | F28: Internet | G28: =SUBTOTAL(9,Jan!I35,Fev!I35,Mar!I35,Abr!I35,Mai!I35,Jun!I35,Jul!I35,Ago!I35,Set!I35,Out!I35,Nov!I35,Dez!I35) -> 90 | I28: Projeto PC | M28: =SUM(L30:L44)-SUM(K30:K44) -> 3332.14
C29: Almoço fora | D29: =SUBTOTAL(9,Fev!D37,Fev!D37,Mar!D37,Abr!D37,Mai!D37,Jun!D37,Jul!D37,Ago!D37,Set!D37,Out!D37,Nov!D37,Dez!D37) -> 0 | F29: Planos/assinaturas | G29: =SUBTOTAL(9,Jan!I36,Fev!I36,Mar!I36,Abr!I36,Mai!I36,Jun!I36,Jul!I36,Ago!I36,Set!I36,Out!I36,Nov!I36,Dez!I36) -> 397.6 | I29: Peça | J29: Local da compra | K29: custo | L29: valor cheio | M29: valor economizado
C30: Lanches / Snacks | D30: =SUBTOTAL(9,Fev!D38,Fev!D38,Mar!D38,Abr!D38,Mai!D38,Jun!D38,Jul!D38,Ago!D38,Set!D38,Out!D38,Nov!D38,Dez!D38) -> 0 | F30: Agua | G30: =SUBTOTAL(9,Jan!I37,Fev!I37,Mar!I37,Abr!I37,Mai!I37,Jun!I37,Jul!I37,Ago!I37,Set!I37,Out!I37,Nov!I37,Dez!I37) -> 0 | I30: gabinete | J30: shoope (pichau) | K30: 201.64 | L30: =200.05+10+10+64 -> 284.05 | M30: =L30-K30 -> 82.41
D31: =SUBTOTAL(9,Fev!D39,Fev!D39,Mar!D39,Abr!D39,Mai!D39,Jun!D39,Jul!D39,Ago!D39,Set!D39,Out!D39,Nov!D39,Dez!D39) -> 0 | F31: Luz | G31: =SUBTOTAL(9,Jan!I38,Fev!I38,Mar!I38,Abr!I38,Mai!I38,Jun!I38,Jul!I38,Ago!I38,Set!I38,Out!I38,Nov!I38,Dez!I38) -> 0 | I31: placa mãe | J31: Terabyte | K31: 1289.99 | L31: 1517.64 | M31: =L31-K31 -> 227.65
F32: Gasolina | G32: =SUBTOTAL(9,Jan!I39,Fev!I39,Mar!I39,Abr!I39,Mai!I39,Jun!I39,Jul!I39,Ago!I39,Set!I39,Out!I39,Nov!I39,Dez!I39) -> 541.3 | I32: processador | J32: Igor | K32: 700 | L32: 1000 | M32: =L32-K32 -> 300
B33: Lazer | C33: Delivery (iFood, etc) | D33: =SUBTOTAL(9,Fev!D41,Fev!D41,Mar!D41,Abr!D41,Mai!D41,Jun!D41,Jul!D41,Ago!D41,Set!D41,Out!D41,Nov!D41,Dez!D41) -> 47.88 | F33: Dizimos | G33: =SUBTOTAL(9,Jan!I40,Fev!I40,Mar!I40,Abr!I40,Mai!I40,Jun!I40,Jul!I40,Ago!I40,Set!I40,Out!I40,Nov!I40,Dez!I40) -> 1220 | H33: pc - bruto | I33: cooler | J33: amazon | K33: 128 | L33: 176 | M33: =L33-K33 -> 48
B34: =SUM(D33:D40) -> 673.39 | C34: Cinema / Shows | D34: =SUBTOTAL(9,Fev!D42,Fev!D42,Mar!D42,Abr!D42,Mai!D42,Jun!D42,Jul!D42,Ago!D42,Set!D42,Out!D42,Nov!D42,Dez!D42) -> 155 | F34: Ofertas | G34: =SUBTOTAL(9,Jan!I41,Fev!I41,Mar!I41,Abr!I41,Mai!I41,Jun!I41,Jul!I41,Ago!I41,Set!I41,Out!I41,Nov!I41,Dez!I41) -> 40 | H34: =SUM(K30:K36) -> 5165.22 | I34: fonte | J34: amazon | K34: 320.74 | L34: 385 | M34: =L34-K34 -> 64.26
C35: Passeios / Viagens | D35: =SUBTOTAL(9,Fev!D43,Fev!D43,Mar!D43,Abr!D43,Mai!D43,Jun!D43,Jul!D43,Ago!D43,Set!D43,Out!D43,Nov!D43,Dez!D43) -> 0 | F35: Parcelas | G35: =SUBTOTAL(9,Jan!I42,Fev!I42,Mar!I42,Abr!I42,Mai!I42,Jun!I42,Jul!I42,Ago!I42,Set!I42,Out!I42,Nov!I42,Dez!I42) -> 3914.36 | I35: ram | J35: magalu | K35: 1715.14 | L35: 2017.8 | M35: =L35-K35 -> 302.66
C36: Compras por impulso (não essenciais) | D36: =SUBTOTAL(9,Fev!D44,Fev!D44,Mar!D44,Abr!D44,Mai!D44,Jun!D44,Jul!D44,Ago!D44,Set!D44,Out!D44,Nov!D44,Dez!D44) -> 0 | F36: Saúde | G36: =SUBTOTAL(9,Jan!I43,Fev!I43,Mar!I43,Abr!I43,Mai!I43,Jun!I43,Jul!I43,Ago!I43,Set!I43,Out!I43,Nov!I43,Dez!I43) -> 0 | I36: ssd | J36: mercado livre | K36: 809.71 | L36: 1000 | M36: =L36-K36 -> 190.29
C37: Jogos / Games / Aplicativos pagos | D37: =SUBTOTAL(9,Fev!D45,Fev!D45,Mar!D45,Abr!D45,Mai!D45,Jun!D45,Jul!D45,Ago!D45,Set!D45,Out!D45,Nov!D45,Dez!D45) -> 0 | F37: Investimento | G37: =SUBTOTAL(9,C22:N22) -> 6100.33 | I37: placa de video | J37: mercado livre | K37: 2378 | L37: 3669 | M37: =L37-K37 -> 1291
C38: Saídas com amigos | D38: =SUBTOTAL(9,Fev!D46,Fev!D46,Mar!D46,Abr!D46,Mai!D46,Jun!D46,Jul!D46,Ago!D46,Set!D46,Out!D46,Nov!D46,Dez!D46) -> 470.51 | G38: =SUBTOTAL(9,Jan!I45,Fev!I45,Mar!I45,Abr!I45,Mai!I45,Jun!I45,Jul!I45,Ago!I45,Set!I45,Out!I45,Nov!I45,Dez!I45) -> 0 | I38: pen drive | J38: mercado livre | K38: 78.9 | L38: 93.24 | M38: =L38-K38 -> 14.34
D39: =SUBTOTAL(9,Fev!D47,Fev!D47,Mar!D47,Abr!D47,Mai!D47,Jun!D47,Jul!D47,Ago!D47,Set!D47,Out!D47,Nov!D47,Dez!D47) -> 0 | I39: Monitor | J39: Terabyte | K39: 630 | L39: 741 | M39: =L39-K39 -> 111
D40: =SUBTOTAL(9,Fev!D48,Fev!D48,Mar!D48,Abr!D48,Mai!D48,Jun!D48,Jul!D48,Ago!D48,Set!D48,Out!D48,Nov!D48,Dez!D48) -> 0 | I40: teclado | J40: aliespress | K40: 394 | L40: 765 | M40: =L40-K40 -> 371
I41: ventoinhas | J41: aliespress | K41: 208.14 | L41: 230
I42: pasta termica | J42: mercado livre | K42: 59.9 | L42: 103.9 | M42: =L42-K42 -> 44
B43: Despesas | C43: Presentes e datas comemorativas | D43: =SUBTOTAL(9,Fev!D50,Fev!D50,Mar!D50,Abr!D50,Mai!D50,Jun!D50,Jul!D50,Ago!D50,Set!D50,Out!D50,Nov!D50,Dez!D50) -> 298.4 | H43: perifericos | I43: Mouse | J43: aliespress | K43: 175 | L43: 373.58 | M43: =L43-K43 -> 198.58
B44: =SUM(D43:D49) -> 1366.38 | C44: Doações / Contribuições | D44: =SUBTOTAL(9,Fev!D51,Fev!D51,Mar!D51,Abr!D51,Mai!D51,Jun!D51,Jul!D51,Ago!D51,Set!D51,Out!D51,Nov!D51,Dez!D51) -> 0 | H44: =SUM(K38:K44) -> 1652.7 | I44: Mouse pad | J44: aliespress | K44: 106.76 | L44: 171.85 | M44: =L44-K44 -> 65.09
C45: Taxas bancárias / Pix por engano | D45: =SUBTOTAL(9,Fev!D52,Fev!D52,Mar!D52,Abr!D52,Mai!D52,Jun!D52,Jul!D52,Ago!D52,Set!D52,Out!D52,Nov!D52,Dez!D52) -> 0
C46: Compras online aleatórias | D46: =SUBTOTAL(9,Fev!D53,Fev!D53,Mar!D53,Abr!D53,Mai!D53,Jun!D53,Jul!D53,Ago!D53,Set!D53,Out!D53,Nov!D53,Dez!D53) -> 407.82 | I46: total | L46: =SUM(H34,H44) -> 6817.92
C47: Manutenção da casa (lâmpada, pilha, etc) | D47: =SUBTOTAL(9,Fev!D54,Fev!D54,Mar!D54,Abr!D54,Mai!D54,Jun!D54,Jul!D54,Ago!D54,Set!D54,Out!D54,Nov!D54,Dez!D54) -> 0
...

Sheet Gastos Fixos anual

Sheet Modelo
B2: MÊS | C2: entradas | D2: valor | F2: Saldo mensal
B3: salário | F3: =SUM(D3:D7) -> 0 | M3: Topicos | N3: Sub-tópicos | P3: Alimentação | R3: Internet
B4: Fotografia | F4: =SUM(F11:F32) -> 0 | M4: =P3 -> Alimentação | N4: Doces | P4: Lazer | R4: Planos/assinaturas
